Workbook

Sheet Data Collection Sheet
C1: YoY growth = | D1: 1.15 | E1: % | G1: Month | I1: Jan'22 | J1: Feb'22 | K1: Mar'22 | L1: Apr'22 | M1: May'22 | N1: Jun'22 | O1: Jul'22 | P1: Aug'22 | Q1: Sep'22 | R1: Oct'22 | S1: Nov'22 | T1: Dec'22 | U1: Jan'23 | V1: Feb'23 | W1: Mar'23 | X1: Apr'23 | Y1: May'23 | Z1: Jun'23 | AA1: Jul'23 | AB1: Aug'23 | AC1: Sep'23 | AD1: Oct'23 | AE1: Nov'23 | AF1: Dec'23 | AG1: Jan'24 | AH1: Feb'24 | AI1: Mar'24 | AJ1: Apr'24 | AK1: May'24 | AL1: Jun'24 | AM1: Jul'24 | AN1: Aug'24 | AO1: Sep'24 | AP1: Oct'24 | AQ1: Nov'24 | AR1: Dec'24 | AS1: Jan'25 | AT1: Feb'25 | AU1: Mar'25 | AV1: Apr'25 | AW1: May'25 | AX1: Jun'25 | AY1: Jul'25 | AZ1: Aug'25 | BA1: Sep'25 | BB1: Oct'25 | BC1: Nov'25 | BD1: Dec'25 | BE1: Jan'26 | BF1: Feb'26 | BG1: Mar'26 | BH1: Apr'26 | BI1: May'26 | BJ1: Jun'26 | BK1: Jul'26 | BL1: Aug'26
D2: 4 | G2: TOTAL CAPACITY ON ARRAY (TB) | I2: =$G$25+$G$55+$G$69+$G$92+$G$100+$G$109 -> 337.81 | J2: =$G$25+$G$55+$G$69+$G$92+$G$100+$G$109 -> 337.81 | K2: =$G$25+$G$55+$G$69+$G$92+$G$100+$G$109 -> 337.81 | L2: =$G$25+$G$55+$G$69+$G$92+$G$100+$G$109 -> 337.81 | M2: =$G$25+$G$55+$G$69+$G$92+$G$100+$G$109 -> 337.81 | N2: =$G$25+$G$55+$G$69+$G$92+$G$100+$G$109 -> 337.81 | O2: =$G$25+$G$55+$G$69+$G$92+$G$100+$G$109 -> 337.81 | P2: =$G$25+$G$55+$G$69+$G$92+$G$100+$G$109 -> 337.81 | ... AF2: =$G$25+$G$55+$G$69+$G$92+$G$100+$G$109 -> 337.81 | AG2: =$G$25+$G$55+$G$69+$G$92+$G$109 -> 325.1 | AH2: =$G$25+$G$55+$G$69+$G$92+$G$109 -> 325.1 | AI2: =$G$25+$G$55+$G$69+$G$92+$G$109 -> 325.1 | AJ2: =$G$25+$G$55+$G$69+$G$92+$G$109 -> 325.1 | AK2: =$G$25+$G$55+$G$69+$G$92+$G$109 -> 325.1 | AL2: =$G$25+$G$55+$G$69+$G$92+$G$109 -> 325.1 | AM2: =$G$25+$G$55+$G$69+$G$92+$G$109 -> 325.1 | AN2: =$G$25+$G$55+$G$69+$G$92+$G$109 -> 325.1 | ... AQ2: =$G$25+$G$55+$G$69+$G$92+$G$109 -> 325.1 | AR2: =$G$25+$G$55+$G$69+$G$92+$G$109+$G$118+$G$125+$G$132+$G$138+$G$144+$G$150+$G$156+$G$162 -> 611.2 | AS2: =$G$25+$G$55+$G$69+$G$92+$G$109+$G$118+$G$125+$G$132+$G$138+$G$144+$G$150+$G$156+$G$162 -> 611.2 | AT2: =$G$25+$G$55+$G$69+$G$92+$G$109+$G$118+$G$125+$G$132+$G$138+$G$144+$G$150+$G$156+$G$162 -> 611.2 | AU2: =$G$25+$G$55+$G$69+$G$92+$G$109+$G$118+$G$125+$G$132+$G$138+$G$144+$G$150+$G$156+$G$162 -> 611.2 | AV2: =$G$25+$G$55+$G$69+$G$92+$G$109+$G$118+$G$125+$G$132+$G$138+$G$144+$G$150+$G$156+$G$162 -> 611.2 | AW2: =$G$25+$G$55+$G$69+$G$92+$G$109+$G$118+$G$125+$G$132+$G$138+$G$144+$G$150+$G$156+$G$162 -> 611.2 | AX2: =$G$25+$G$55+$G$69+$G$92+$G$109+$G$118+$G$125+$G$132+$G$138+$G$144+$G$150+$G$156+$G$162 -> 611.2 | AY2: =$G$25+$G$55+$G$69+$G$92+$G$109+$G$118+$G$125+$G$132+$G$138+$G$144+$G$150+$G$156+$G$162 -> 611.2 | ... BG2: =$G$25+$G$55+$G$69+$G$92+$G$109+$G$118+$G$125+$G$132+$G$138+$G$144+$G$150+$G$156+$G$162 -> 611.2 | BH2: =$G$25+$G$55+$G$69+$G$92+$G$109+$G$118+$G$125+G132+G138+G144+G150+G156+G162 -> 611.2 | BI2: =$G$25+$G$55+$G$69+$G$92+$G$109+$G$118+$G$125+G132+G138+G144+G150+G156+G162 -> 611.2 | BJ2: =$G$25+$G$55+$G$69+$G$78+$G$92+$G$109+$G$118+$G$125+G132+G138+G144+G150+G156+G162 -> 809.2 | BK2: =$G$25+$G$55+$G$69+$G$78+$G$92+$G$109+$G$118+$G$125+H132+H138+H144+H150+H156+H162 -> 574.5 | BL2: =$G$25+$G$55+$G$69+$G$78+$G$92+$G$109+$G$118+$G$125+I132+I138+I144+I150+I156+I162 -> 917.8
G3: TOTAL IN-USE ON ARRAY | I3: =I24+I54+I68+I91+I99+I108+I118+I124+I131+I137+I143+I149+I155+I161 -> 296.46124 | J3: =J24+J54+J68+J91+J99+J108+J118+J124+J131+J137+J143+J149+J155+J161 -> 295.8236 | K3: =K24+K54+K68+K91+K99+K108+K118+K124+K131+K137+K143+K149+K155+K161 -> 360.6608 | L3: =L24+L54+L68+L91+L99+L108+L118+L124+L131+L137+L143+L149+L155+L161 -> 354.481 | M3: =M24+M54+M68+M91+M99+M108+M118+M124+M131+M137+M143+M149+M155+M161 -> 353.823 | N3: =N24+N54+N68+N91+N99+N108+N118+N124+N131+N137+N143+N149+N155+N161 -> 328.31 | O3: =O24+O54+O68+O91+O99+O108+O118+O124+O131+O137+O143+O149+O155+O161 -> 333.107 | P3: =P24+P54+P68+P91+P99+P108+P118+P124+P131+P137+P143+P149+P155+P161 -> 309.91 | ... BI3: =BI24+BI54+BI68+BI91+BI99+BI108+BI118+BI124+BI131+BI137+BI143+BI149+BI155+BI161 -> 413.58 | BJ3: =BJ24+BJ54+BJ68+BJ77+BJ91+BJ99+BJ108+BJ118+BJ124+BJ131+BJ137+BJ143+BJ149+BJ155+BJ161 -> 493.44 | BK3: =BK24+BK54+BK68+BK77+BK91+BK99+BK108+BK118+BK124+BK131+BK137+BK143+BK149+BK155+BK161 -> 495.69 | BL3: =BL24+BL54+BL68+BL77+BL91+BL99+BL108+BL118+BL124+BL131+BL137+BL143+BL149+BL155+BL161 -> 494.79
G4: TOTAL AVAILABLE ON ARRAY | I4: =I25+I55+I69+I92+I100+I109 -> 125.73876 | J4: =J25+J55+J69+J92+J100+J109 -> 127.4204 | K4: =K25+K55+K69+K92+K100+K109 -> 106.2784 | L4: =L25+L55+L69+L92+L100+L109 -> 120.66 | M4: =M25+M55+M69+M92+M100+M109 -> 106.727 | N4: =N25+N55+N69+N92+N100+N109 -> 87.79 | O4: =O25+O55+O69+O92+O100+O109 -> 80.593 | P4: =P25+P55+P69+P92+P100+P109 -> 102.79 | ... BI4: =BI25+BI55+BI69+BI92+BI100+BI109 -> 67.25 | BJ4: =BJ25+BJ55+BJ69+BJ92+BJ100+BJ109+BJ118+BJ125+BJ132+BJ138+BJ144+BJ150+BJ156+BJ162 -> 414.02 | BK4: =BK25+BK55+BK69+BK92+BK100+BK109+BK118+BK125+BK132+BK138+BK144+BK150+BK156+BK162 -> 412.89 | BL4: =BL25+BL55+BL69+BL92+BL100+BL109+BL118+BL125+BL132+BL138+BL144+BL150+BL156+BL162 -> 412.7
B8: Site | C8: Storage Unit | D8: Host group | E8: Workload type (Volume Group) | G8: 1. From ARRAY Level 2. Total USABLE data 3. before data-reduc. 4. in Tbyte | BN8: 1. Looking on Compute level 2. Data-actual in-use 3. After data-redu. 4. in Tbyte
I9: Jan'22 | J9: Feb'22 | K9: Mar'22 | L9: Apr'22 | M9: May'22 | N9: Jun'22 | O9: Jul'22 | P9: Aug'22 | Q9: Sep'22 | R9: Oct'22 | S9: Nov'22 | T9: Dec'22 | U9: Jan'23 | V9: Feb'23 | W9: Mar'23 | X9: Apr'23 | Y9: May'23 | Z9: Jun'23 | AA9: Jul'23 | AB9: Aug'23 | AC9: Sep'23 | AD9: Oct'23 | AE9: Nov'23 | AF9: Dec'23 | AG9: Jan'24 | AH9: Feb'24 | AI9: Mar'24 | AJ9: Apr'24 | AK9: May'24 | AL9: Jun'24 | AM9: Jul'24 | AN9: Aug'24 | AO9: Sep'24 | AP9: Oct'24 | AQ9: Nov'24 | AR9: Dec'24 | AS9: Jan'25 | AT9: Feb'25 | AU9: Mar'25 | AV9: Apr'25 | AW9: May'25 | AX9: Jun'25 | AY9: Jul'25 | AZ9: Aug'25 | BA9: Sep'25 | BB9: Oct'25 | BC9: Nov'25 | BD9: Dec'25 | BE9: Jan'26 | BF9: Feb'26 | BG9: Mar'26 | BH9: Apr'26 | BI9: May'26 | BJ9: Jun'26 | BK9: Jul'26 | BL9: Aug'26 | BN9: Jan'22 | BO9: Feb'22 | BP9: Mar'22 | BQ9: Apr'22 | BR9: May'22 | BS9: Jun'22 | BT9: Jul'22 | BU9: Aug'22 | BV9: Sep'22 | BW9: Oct'22 | BX9: Nov'22 | BY9: Dec'22 | BZ9: Jan'23 | CA9: Feb'23 | CB9: Mar'23 | CC9: Apr'23 | CD9: May'23 | CE9: Jun'23 | CF9: Jul'23 | CG9: Aug'23 | CH9: Sep'23 | CI9: Oct'23 | CJ9: Nov'23 | CK9: Dec'23 | CL9: Jan'24 | CM9: Feb'24 | CN9: Mar'24 | CO9: Apr'24 | CP9: May'24 | CQ9: Jun'24 | CR9: July'24 | CS9: Aug'24 | CT9: Sep'24 | CU9: Oct'24 | CV9: Nov'24 | CW9: Dec'24 | CX9: Jan'25
B10: MacPark | C10: M20 | D10: CISCO-FlashStack (VMware) | E10: Vmware-FILESERVER | I10: 0.4 | J10: 0.345 | K10: 0.32 | L10: 0.33 | M10: 0.36 | N10: 0.22 | O10: 0.21 | P10: 0.23 | Q10: 0.2 | R10: 0.24 | S10: 0.26 | AV10: 8.56 | AW10: 8.59 | AX10: 8.67 | AY10: 8.74 | AZ10: 8.77 | BA10: 8.79 | BB10: 8.65 | BC10: 8.66 | BD10: 8.66 | BE10: 8.69 | BF10: 8.76 | BG10: 8.79 | BH10: 9.03 | BI10: 0.02 | BJ10: 0 | BK10: 0 | BL10: 0
B11: aum-pc-prd01 | E11: VMware - SQL - RDM | I11: 0.7 | J11: 0.745 | K11: 0.74 | L11: 0.74 | M11: 1.04 | N11: 0.06 | O11: 0.058 | P11: 0.06 | Q11: 0.06 | R11: 0.06 | S11: 0.06 | T11: 0.26 | AF11: 0.45 | AG11: 0.47 | AH11: 0.48 | AI11: 0.47 | AJ11: 0.5 | AK11: 0.61 | AL11: 0.67 | AM11: 0.74 | AN11: 0.77 | AO11: 0.82 | AP11: 0.83 | AQ11: 0.77 | AR11: 0.84 | AS11: 0.81 | AT11: 1.23 | AU11: 1.23 | AV11: 1.37 | AW11: 1.45 | AX11: 1.51 | AY11: 1.45 | AZ11: 1.49 | BA11: 1.53 | BB11: 1.56 | BC11: 1.6 | BD11: 1.57 | BE11: 1.59 | BF11: 1.69 | BG11: 1.78 | BH11: 1.85 | BI11: 1.79 | BJ11: 1.7 | BK11: 1.75 | BL11: 1.76
E12: VMware - SRM | I12: 26.6 | J12: 22.08 | K12: 23.63 | L12: 22.73 | M12: 11.25 | N12: 13.45 | O12: 13.02 | P12: 12.67 | Q12: 12.56 | R12: 11.09 | S12: 11.46 | T12: 0.056 | U12: 0.06 | V12: 0.06 | W12: 0.06 | X12: 0.06 | Y12: 0.06 | Z12: 0.06 | AA12: 0.06 | AB12: 0.06 | AC12: 0.06 | AD12: 0.06 | AE12: 0.06 | AF12: 0.07 | AG12: 0.07 | AH12: 0.07 | AI12: 0.07 | AJ12: 0.07 | AK12: 0.07 | AL12: 0.06 | AM12: 0.06 | AN12: 0.06 | AO12: 0.06 | AP12: 0.06 | AQ12: 0.06 | AR12: 0.06 | AS12: 0.06 | AT12: 0.06 | AU12: 0.06 | AV12: 0.06 | AW12: 0.06 | AX12: 0.06 | AY12: 0.06 | AZ12: 0.06 | BA12: 0.06 | BB12: 0.06 | BC12: 0.06 | BD12: 0.06 | BE12: 0.06 | BF12: 0.06 | BG12: 0.06 | BH12: 0.06 | BI12: 0.06 | BJ12: 0.06 | BK12: 0.06 | BL12: 0.06
E13: VMware - VMFS | T13: 11.9 | U13: 12.06 | V13: 21.55 | W13: 21.95 | X13: 23.55 | Y13: 14.5 | Z13: 15.24 | AA13: 15.64 | AB13: 16.49 | AC13: 16.17 | AD13: 16.35 | AE13: 16.77 | AF13: 16.43 | AG13: 16.44 | AH13: 17.55 | AI13: 17.1 | AJ13: 17.72 | AK13: 17.09 | AL13: 25.03 | AM13: 25.8 | AN13: 26.12 | AO13: 26.11 | AP13: 24.71 | AQ13: 24.64 | AR13: 24.6 | AS13: 25.41 | AT13: 24.91 | AU13: 24.91 | AV13: 24.71 | AW13: 24.89 | AX13: 25.54 | AY13: 25.66 | AZ13: 25.94 | BA13: 25.35 | BB13: 25.64 | BC13: 25.07 | BD13: 25.19 | BE13: 25.99 | BF13: 26.2 | BG13: 27.04 | BH13: 26.8 | BI13: 28.43 | BJ13: 28 | BK13: 27.6 | BL13: 26
D14: CISCO-FlashStack (x86 RAC) | E14: X86-ORACLE-RAC-NWC-DR | I14: 0.216 | J14: 0.218 | K14: 0.19 | L14: 0.19 | M14: 0.19 | N14: 0.21 | O14: 0.208 | P14: 0.21 | Q14: 0.21 | R14: 0.21 | S14: 0.21 | T14: 0.207 | U14: 0.19 | V14: 0.19 | W14: 0.19 | X14: 0.19 | Y14: 0.2 | Z14: 0.21 | AA14: 0.22 | AB14: 0.23 | AC14: 0.23 | AD14: 0.23 | AE14: 0.24 | AF14: 0.24 | AG14: 0.2 | AH14: 0.21 | AI14: 0.22 | AJ14: 0.22 | AK14: 0.23 | AL14: 0.23 | AM14: 0.23 | AN14: 0.23 | AO14: 0.23 | AP14: 0.22 | AQ14: 0.21 | AR14: 0.21 | AS14: 0.22 | AT14: 0.23 | AU14: 0.23 | AV14: 0.24 | AW14: 0.24 | AX14: 0.24 | AY14: 0.24 | AZ14: 0.23 | BA14: 0.22 | BB14: 0.22 | BC14: 0.21 | BD14: 0.21 | BE14: 0.21 | BF14: 0.21 | BG14: 0.21 | BH14: 0.21 | BI14: 0.21 | BJ14: 0.21 | BK14: 0.21 | BL14: 0.22 | BO14: 0.42 | BP14: 0.43 | BQ14: 0.4 | BR14: 0.4 | BS14: 0.4 | BT14: 0.4 | BU14: 0.4 | BV14: 0.4 | BW14: 0.4 | BX14: 0.48 | BY14: 0.52 | BZ14: 0.5 | CA14: 0.5 | CB14: 0.5 | CC14: 0.5 | CD14: 0.5 | CE14: 0.5 | CF14: 0.5 | CG14: 0.5 | CH14: 0.5 | CI14: 0.5 | CJ14: 0.5 | CK14: 0.5 | CL14: 0.5 | CM14: 0.5 | CN14: 0.5 | CO14: 0.5 | CP14: 0.5 | CQ14: 0.5 | CR14: 0.5 | CS14: 0.5
E15: X86-ORACLE-RAC-NWC-NPRD | I15: 0.56 | J15: 0.557 | K15: 0.558 | L15: 0.56 | M15: 0.5 | N15: 0.51 | O15: 0.437 | P15: 0.42 | Q15: 0.45 | R15: 0.44 | S15: 0.44 | T15: 0.44 | U15: 0.45 | V15: 0.44 | W15: 0.45 | X15: 0.44 | Y15: 0.45 | Z15: 0.46 | AA15: 0.47 | AB15: 0.48 | AC15: 0.49 | AD15: 0.49 | AE15: 0.49 | AF15: 0.5 | AG15: 0.49 | AH15: 0.52 | AI15: 0.53 | AJ15: 0.51 | AK15: 0.52 | AL15: 0.52 | AM15: 0.52 | AN15: 0.52 | AO15: 0.53 | AP15: 0.51 | AQ15: 0.5 | AR15: 0.5 | AS15: 0.5 | AT15: 0.5 | AU15: 0.5 | AV15: 0.53 | AW15: 0.48 | AX15: 0.49 | AY15: 0.47 | AZ15: 0.49 | BA15: 0.49 | BB15: 0.49 | BC15: 0.47 | BD15: 0.47 | BE15: 0.45 | BF15: 0.49 | BG15: 0.48 | BH15: 0.46 | BI15: 0.4 | BJ15: 0.4 | BK15: 0.4 | BL15: 0.43 | BO15: 1.13 | BP15: 1.13 | BQ15: 1.5 | BR15: 1.5 | BS15: 1.14 | BT15: 1.65 | BU15: 1.7 | BV15: 1.7 | BW15: 1.7 | BX15: 1.61 | BY15: 1.12 | BZ15: 1.2 | CA15: 1.2 | CB15: 1.1 | CC15: 1.1 | CD15: 1.1 | CE15: 1.1 | CF15: 1.1 | CG15: 1.1 | CH15: 1.2 | CI15: 1.2 | CJ15: 1.2 | CK15: 1.2 | CL15: 1.2 | CM15: 1.2 | CN15: 1.2 | CO15: 1.2 | CP15: 1.2 | CQ15: 1.2 | CR15: 1.2 | CS15: 1.2
E16: X86-ORACLE-RAC-OS-APP-NPRD | I16: 0.22 | J16: 0.228 | K16: 0.232 | L16: 0.23 | M16: 0.23 | N16: 0.24 | O16: 0.251 | P16: 0.25 | Q16: 0.25 | R16: 0.25 | S16: 0.26 | T16: 0.256 | U16: 0.26 | V16: 0.26 | W16: 0.26 | X16: 0.26 | Y16: 0.27 | Z16: 0.27 | AA16: 0.27 | AB16: 0.28 | AC16: 0.28 | AD16: 0.28 | AE16: 0.28 | AF16: 0.29 | AG16: 0.29 | AH16: 0.29 | AI16: 0.29 | AJ16: 0.29 | AK16: 0.29 | AL16: 0.29 | AM16: 0.29 | AN16: 0.29 | AO16: 0.29 | AP16: 0.28 | AQ16: 0.27 | AR16: 0.28 | AS16: 0.28 | AT16: 0.28 | AU16: 0.28 | AV16: 0.29 | AW16: 0.3 | AX16: 0.3 | AY16: 0.3 | AZ16: 0.3 | BA16: 0.3 | BB16: 0.3 | BC16: 0.3 | BD16: 0.31 | BE16: 0.31 | BF16: 0.31 | BG16: 0.31 | BH16: 0.31 | BI16: 0.31 | BJ16: 0.31 | BK16: 0.31 | BL16: 0.31 | BO16: 2.8 | BP16: 2.9 | BV16: 2.9 | BW16: 2.9 | BX16: 2.9 | BY16: 2.9
E17: X86-ORACLE-RAC-WC-DEV | I17: 0.15 | J17: 0.157 | K17: 0.205 | L17: 0.22 | M17: 0.01 | N17: 0.01 | O17: 0.0145 | P17: 0.04 | Q17: 0.04 | R17: 0.04 | S17: 0.04 | T17: 0.044 | U17: 0.05 | V17: 0.05 | W17: 0.05 | X17: 0.05 | Y17: 0.05 | Z17: 0.02 | AA17: 0.06 | AB17: 0.23 | AC17: 0.02 | AD17: 0.03 | AE17: 0 | AF17: 0.68 | AG17: 0.72 | AH17: 0.74 | AI17: 0.76 | AJ17: 0.78 | AK17: 0.8 | AL17: 0.8 | AM17: 0.99 | AN17: 1 | AO17: 1 | AP17: 0 | AQ17: 0 | AR17: 0 | AS17: 0 | AT17: 0 | AU17: 0 | AV17: 0 | AW17: 0 | AX17: 0 | AY17: 0 | AZ17: 0 | BA17: 0 | BB17: 0 | BC17: 0 | BD17: 0 | BE17: 0 | BF17: 0 | BG17: 0 | BH17: 0 | BI17: 0 | BJ17: 0 | BK17: 0 | BL17: 0 | BO17: 10.98 | BP17: 10.98 | BQ17: 12.7 | BR17: 12.7 | BS17: 12.75 | BT17: 12.75 | BU17: 12.77 | BV17: 12.77 | BW17: 12.77 | BX17: 12.77 | BY17: 12.8 | BZ17: 13.4 | CA17: 13.4 | CB17: 12.8 | CC17: 12.8 | CD17: 12.8 | CE17: 14.9 | CF17: 14.9 | CG17: 14.9 | CH17: 15.3 | CI17: 15.4 | CJ17: 15.5 | CK17: 15.5 | CL17: 15.5 | CM17: 15.5 | CN17: 15.5 | CO17: 15.5 | CP17: 15.5 | CQ17: 15.5 | CR17: 15.5 | CS17: 15.5
E18: X86-ORACLE-RAC-WC-DR | I18: 1.6 | J18: 1.67 | K18: 1.77 | L18: 1.83 | M18: 0.03 | N18: 0.18 | O18: 0.271 | P18: 0.48 | Q18: 0.58 | R18: 0.69 | S18: 0.97 | T18: 1.011 | U18: 1.07 | V18: 1.13 | W18: 1.38 | X18: 1.36 | Y18: 1.42 | Z18: 0.03 | AA18: 0.1 | AB18: 0.17 | AC18: 0.03 | AD18: 0.1 | AE18: 0.14 | AF18: 0.21 | AG18: 0.25 | AH18: 0.18 | AI18: 0.33 | AJ18: 0.4 | AK18: 0.44 | AL18: 0.88 | AM18: 0.01 | AN18: 0.02 | AO18: 0.03 | AP18: 0 | AQ18: 0 | AR18: 0 | AS18: 0 | AT18: 0 | AU18: 0 | AV18: 0 | AW18: 0 | AX18: 0 | AY18: 0 | AZ18: 0 | BA18: 0 | BB18: 0 | BC18: 0 | BD18: 0 | BE18: 0 | BF18: 0 | BG18: 0 | BH18: 0 | BI18: 0 | BJ18: 0 | BK18: 0 | BL18: 0 | BO18: 12 | BP18: 12.47 | BQ18: 13 | BR18: 13.1 | BS18: 12.98 | BT18: 13 | BU18: 13 | BV18: 13.59 | BW18: 13.89 | BX18: 14.01 | BY18: 14.11 | BZ18: 14.9 | CA18: 15 | CB18: 14.5 | CC18: 14.6 | CD18: 14.8 | CE18: 14.9 | CF18: 15.1 | CG18: 15.1 | CH18: 15.4 | CI18: 15.5 | CJ18: 15.7 | CK18: 15.7 | CL18: 16 | CM18: 16 | CN18: 16.3 | CO18: 16.3 | CP18: 16.3 | CQ18: 17 | CR18: 17.3 | CS18: 17.3
E19: X86-ORACLE-RAC-WC-TST | I19: 0.15 | J19: 0.162 | K19: 0.18 | L19: 0.18 | M19: 0.01 | N19: 0.01 | O19: 0.012 | P19: 0.02 | Q19: 0.03 | R19: 0.03 | S19: 0.03 | T19: 0.0326 | U19: 0.04 | V19: 0.04 | W19: 0.04 | X19: 0.04 | Y19: 0.04 | Z19: 0.004 | AA19: 0.01 | AB19: 0.01 | AC19: 0.01 | AD19: 0.01 | AE19: 0.01 | AF19: 0.01 | AG19: 0.01 | AH19: 0.1 | AI19: 0.11 | AJ19: 0.12 | AK19: 0.12 | AL19: 0.19 | AM19: 0.32 | AN19: 0.33 | AO19: 0.33 | AP19: 0 | AQ19: 0 | AR19: 0 | AS19: 0 | AT19: 0 | AU19: 0 | AV19: 0 | AW19: 0 | AX19: 0 | AY19: 0 | AZ19: 0 | BA19: 0 | BB19: 0 | BC19: 0 | BD19: 0 | BE19: 0 | BF19: 0 | BG19: 0 | BH19: 0 | BI19: 0 | BJ19: 0 | BK19: 0 | BL19: 0 | BO19: 11.57 | BP19: 11.57 | BQ19: 11,6 | BR19: 12.7 | BS19: 12.75 | BT19: 12.75 | BU19: 12.75 | BV19: 12.75 | BW19: 12.75 | BX19: 12.75 | BY19: 12.79 | BZ19: 13.4 | CA19: 13.4 | CB19: 12.8 | CC19: 12.8 | CD19: 12.8 | CE19: 14.9 | CF19: 14.9 | CG19: 14.9 | CH19: 14.9 | CI19: 14.9 | CJ19: 14.9 | CK19: 14.9 | CL19: 15.5 | CM19: 15.5 | CN19: 15.5 | CO19: 15.5 | CP19: 15.5 | CQ19: 15.5 | CR19: 15.5 | CS19: 15.5
E20: X86-ORACLE-RAC-WC-UAT | I20: 0.12 | J20: 0.128 | K20: 0.138 | L20: 0.15 | M20: 0.02 | N20: 0.05 | O20: 0.0485 | P20: 0.05 | Q20: 0.05 | R20: 0.05 | S20: 0.05 | T20: 0.053 | U20: 0.05 | V20: 0.06 | W20: 0.06 | X20: 0.06 | Y20: 0.06 | Z20: 0.004 | AA20: 0.01 | AB20: 0.01 | AC20: 0.01 | AD20: 0.01 | AE20: 0.01 | AF20: 0.01 | AG20: 0.01 | AH20: 0.11 | AI20: 0.11 | AJ20: 0.11 | AK20: 0.26 | AL20: 0.29 | AM20: 0.08 | AN20: 0.02 | AO20: 0.03 | AP20: 0 | AQ20: 0 | AR20: 0 | AS20: 0 | AT20: 0 | AU20: 0 | AV20: 0 | AW20: 0 | AX20: 0 | AY20: 0 | AZ20: 0 | BA20: 0 | BB20: 0 | BC20: 0 | BD20: 0 | BE20: 0 | BF20: 0 | BG20: 0 | BH20: 0 | BI20: 0 | BJ20: 0 | BK20: 0 | BL20: 0 | BO20: 11.62 | BP20: 11.62 | BQ20: 11.6 | BR20: 11.6 | BS20: 12.8 | BT20: 12.8 | BU20: 12.8 | BV20: 12.8 | BW20: 12.8 | BX20: 12.8 | BY20: 12.84 | BZ20: 13.4 | CA20: 13.5 | CB20: 12.8 | CC20: 12.8 | CD20: 12.8 | CE20: 14.9 | CF20: 14.9 | CG20: 14.9 | CH20: 14.9 | CI20: 14.9 | CJ20: 14.9 | CK20: 14.9 | CL20: 14.9 | CM20: 14.9 | CN20: 14.9 | CO20: 14.9 | CP20: 14.9 | CQ20: 14.9 | CR20: 14.9 | CS20: 14.9
E22: SHARED | I22: 13.51 | J22: 13.6 | K22: 13.74 | L22: 14.64 | M22: 13.6 | N22: 13.11 | O22: 12.96 | P22: 13.42 | Q22: 13.53 | R22: 14.66 | S22: 14.95 | T22: 15.14 | U22: 14.65 | V22: 15.27 | W22: 15.43 | X22: 15.35 | Y22: 16.08 | Z22: 16.87 | AA22: 16.63 | AB22: 16.94 | AC22: 16.92 | AD22: 17.99 | AE22: 17.42 | AF22: 16.77 | AG22: 17.15 | AH22: 16.27 | AI22: 14.6 | AJ22: 14.59 | AK22: 14.34 | AL22: 14.22 | AM22: 14.82 | AN22: 14.99 | AO22: 15.04 | AP22: 4.31 | AQ22: 4.21 | AR22: 4.23 | AS22: 4.24 | AT22: 3.62 | AU22: 3.62 | AV22: 4.01 | AW22: 3.62 | AX22: 3.6 | AY22: 3.59 | AZ22: 3.39 | BA22: 3.54 | BB22: 3.39 | BC22: 3.54 | BD22: 3.23 | BE22: 3.67 | BF22: 3.6 | BG22: 3.08 | BH22: 3.19 | BI22: 2.87 | BJ22: 2.87 | BK22: 2.7 | BL22: 4.1
E23: SNAPSHOTS | I23: 0.52 | J23: 0.395 | K23: 0.405 | L23: 0.41 | M23: 0.37 | N23: 0.03 | O23: 0.031 | P23: 0.01 | Q23: 0.03 | R23: 0.04 | S23: 0.04 | T23: 0.043 | U23: 0.05 | V23: 0.05 | W23: 0.05 | X23: 0.08 | Y23: 0.08 | Z23: 0.09 | AA23: 0.12 | AB23: 0.12 | AC23: 0.13 | AD23: 0.02 | AE23: 0.02 | AF23: 0.02 | AG23: 0.02 | AH23: 0.02 | AI23: 0.02 | AJ23: 0.02 | AK23: 0.05 | AL23: 0.06 | AM23: 0.08 | AN23: 0.09 | AO23: 0.09 | AP23: 0.02 | AQ23: 0.2 | AR23: 0.03 | AS23: 0.03 | AT23: 0.03 | AU23: 0.03 | AV23: 0.03 | AW23: 0.03 | AX23: 0.03 | AY23: 0.14 | AZ23: 0.01 | BA23: 0.01 | BB23: 0.01 | BC23: 0.01 | BD23: 0.01 | BE23: 0.01 | BF23: 0.01 | BG23: 0.01 | BH23: 0.01 | BI23: 0.01 | BJ23: 0.01 | BK23: 0.01 | BL23: 0.01
E24: TOTAL IN-USE | I24: =SUM(I10:I23) -> 44.746 | J24: =SUM(J10:J23) -> 40.285 | K24: =SUM(K10:K23) -> 42.108 | L24: =SUM(L10:L23) -> 42.21 | M24: =SUM(M10:M23) -> 27.61 | N24: =SUM(N10:N23) -> 28.08 | O24: =SUM(O10:O23) -> 27.521 | P24: =SUM(P10:P23) -> 27.86 | ... BL24: =SUM(BL10:BL23) -> 32.89 | CE24: Story:
E25: TOTAL AVAILABLE | G25: 51.39 | I25: =49.13-I24 -> 4.384 | J25: =49.13-J24 -> 8.845 | K25: =49.13-K24 -> 7.022 | L25: =49.13-L24 -> 6.92 | M25: =49.13-M24 -> 21.52 | N25: =49.13-N24 -> 21.05 | O25: =49.13-O24 -> 21.609 | P25: =49.13-P24 -> 21.27 | ... R25: =49.13-R24 -> 21.33 | S25: =$G25-S24 -> 22.62 | T25: =$G25-T24 -> 21.9474 | U25: =$G25-U24 -> 22.46 | V25: =$G25-V24 -> 12.29 | W25: =$G25-W24 -> 11.47 | X25: =$G25-X24 -> 9.95 | Y25: =$G25-Y24 -> 18.18 | Z25: =$G25-Z24 -> 18.132 | ... BL25: =$G25-BL24 -> 18.5 | CE25: * Dedup-rate isn't 4.5 due to "shared storage" Excluded. Including shared storage dedup-rate is 2.5
E26: % IN-USE Capacity | I26: =I24/49.13 -> 0.91076735 | J26: =J24/49.13 -> 0.81996743 | K26: =K24/49.13 -> 0.85707307 | L26: =L24/49.13 -> 0.8591492 | M26: =M24/49.13 -> 0.56197842 | N26: =N24/49.13 -> 0.57154488 | O26: =O24/49.13 -> 0.5601669 | P26: =P24/49.13 -> 0.56706697 | ... R26: =R24/49.13 -> 0.56584572 | S26: =S24/$G$25 -> 0.55983654 | T26: =T24/$G$25 -> 0.57292469 | U26: =U24/$G$25 -> 0.56294999 | V26: =V24/$G$25 -> 0.76084841 | W26: =W24/$G$25 -> 0.77680483 | X26: =X24/$G$25 -> 0.80638256 | Y26: =Y24/$G$25 -> 0.64623468 | Z26: =Z24/$G$25 -> 0.64716871 | ... BL26: =BL24/$G$25 -> 0.64000778 | CE26: * Cherwell UniCode - Environment required (CMS - SQL)
CE27: * File-Services growing ==> Read-Only and put new new stuff in TEAMS
B28: MacPark | C28: X50 | D28: ORACLE-T8s | E28: ORACLE-ERPDEV01 | I28: 1.01 | J28: 1.02 | K28: 0.38 | L28: 0.91 | M28: 0.96 | N28: 0.28 | O28: 0.669 | P28: 0.71 | Q28: 0.16 | R28: 0.81 | S28: 0.99 | T28: 1.26 | U28: 1.26 | V28: 1.66 | W28: 1.62 | X28: 0.36 | Y28: 0.64 | Z28: 0.68 | AA28: 0.41 | AB28: 0.84 | AC28: 0.86 | AD28: 0.62 | AE28: 0.6 | AF28: 0.73 | AG28: 0.73 | AH28: 0.46 | AI28: 0.64 | AJ28: 0.43 | AK28: 0.47 | AL28: 0.71 | AM28: 0.99 | AN28: 0.9 | AO28: 1.18 | AP28: 1.34 | AQ28: 1.47 | AR28: 1.57 | AS28: 1.62 | AT28: 1.68 | AU28: 1.68 | AV28: 0.24 | AW28: 0.93 | AX28: 1.07 | AY28: 1.14 | AZ28: 1.17 | BA28: 1.21 | BB28: 0.88 | BC28: 1.02 | BD28: 1.12 | BE28: 1.44 | BF28: 1.51 | BG28: 0.77 | BH28: 0.93 | BI28: 1.11 | BJ28: 1.05 | BK28: 0.75 | BL28: 0.8 | BO28: 14.10411 | BP28: 15.32212 | BQ28: 15.3 | BR28: 14.97 | BS28: 15.48 | BT28: 15.66 | BU28: 15.5 | BV28: 15.54 | BW28: 16.05 | BX28: 16.36 | BY28: 16.57 | BZ28: 17.7 | CA28: 17.7 | CB28: 16.7 | CC28: 17.1 | CD28: 17.2 | CE28: 17.2 | CF28: 17.8 | CG28: 17.8 | CH28: 17.9 | CI28: 18 | CJ28: 18.4 | CK28: 18.4 | CL28: 19 | CM28: 19 | CN28: 19
B29: aum-pc-prd02 | D29: ORACLE-T7s | E29: ORACLE-ERPDR01 | I29: 0.07135 | J29: 0.386 | K29: 0.28 | L29: 0.31 | M29: 0.04 | N29: 0.3 | O29: 0.295 | P29: 0.04 | Q29: 0.29 | R29: 0.33 | S29: 0.27 | T29: 0.108 | U29: 0.61 | V29: 0.14 | W29: 0.29 | X29: 0.28 | Y29: 0.28 | Z29: 0.26 | AA29: 0.36 | AB29: 0.27 | AC29: 0.45 | AD29: 0.4 | AE29: 0.39 | AF29: 0.4 | AG29: 0.3 | AH29: 0.29 | AI29: 0.3 | AJ29: 0.24 | AK29: 0.05 | AL29: 0.41 | AM29: 0.25 | AN29: 0.3 | AO29: 1.18 | AP29: 0.35 | AQ29: 0.34 | AR29: 0.43 | AS29: 0.44 | AT29: 0.06 | AU29: 0.06 | AV29: 0.42 | AW29: 0.32 | AX29: 0.36 | AY29: 0.42 | AZ29: 0.37 | BA29: 0.34 | BB29: 0.08 | BC29: 0.05 | BD29: 0.5 | BE29: 0.17 | BF29: 0.32 | BG29: 0.32 | BH29: 0.52 | BI29: 0.68 | BJ29: 0.27 | BK29: 0.51 | BL29: 0.57 | BO29: 14.97683 | BP29: 15.32339 | BQ29: 15.6 | BR29: 15.6 | BS29: 15.5 | BT29: 15.8 | BU29: 15.76 | BV29: 15.94 | BW29: 16.12 | BX29: 16.34 | BY29: 16.8 | BZ29: 17.8 | CA29: 16.9 | CB29: 17.1 | CC29: 17.4 | CD29: 17.5 | CE29: 17.8 | CF29: 17.9 | CG29: 17.9 | CH29: 18.4 | CI29: 18.4 | CJ29: 18.8 | CK29: 18.8 | CL29: 19.3 | CM29: 19.3 | CN29: 19.8
D30: ORACLE-T8s | E30: ORACLE-ERPEPE01 | I30: 0.06638 | J30: 0.456 | K30: 0.34 | L30: 0.33 | M30: 0.05 | N30: 0.12 | O30: 0.516 | P30: 0.34 | Q30: 0.14 | R30: 0.6 | S30: 0.28 | T30: 0.165 | U30: 1.06 | V30: 0.2 | W30: 0.36 | X30: 0.3 | Y30: 0.36 | Z30: 0.3 | AA30: 0.66 | AB30: 0.57 | AC30: 0.41 | AD30: 0.23 | AE30: 0.41 | AF30: 0.18 | AG30: 0.32 | AH30: 0.34 | AI30: 0.33 | AJ30: 0.44 | AK30: 0.04 | AL30: 1.1 | AM30: 0.46 | AN30: 0.37 | AO30: 0.62 | AP30: 0.79 | AQ30: 0.4 | AR30: 0.43 | AS30: 0.46 | AT30: 0.45 | AU30: 0.45 | AV30: 0.34 | AW30: 0.34 | AX30: 0.42 | AY30: 0.42 | AZ30: 0.43 | BA30: 0.4 | BB30: 0.11 | BC30: 0.54 | BD30: 0.39 | BE30: 0.2 | BF30: 0.31 | BG30: 0.59 | BH30: 0.55 | BI30: 0.57 | BJ30: 0.26 | BK30: 0.43 | BL30: 0.47 | BO30: 14.96425 | BP30: 15.32111 | BQ30: 15.6 | BR30: 15.37 | BS30: 15.49 | BT30: 15.82 | BU30: 15.75 | BV30: 15.93 | BW30: 16.12 | BX30: 16.34 | BY30: 16.8 | BZ30: 17.8 | CA30: 17.9 | CB30: 17.1 | CC30: 17.4 | CD30: 17.5 | CE30: 17.8 | CF30: 17.9 | CG30: 17.9 | CH30: 18.3 | CI30: 18.3 | CJ30: 18.8 | CK30: 18.8 | CL30: 19.3 | CM30: 19.3 | CN30: 19.8
D31: ORACLE-T8s | E31: ORACLE-ERPHRS01 | I31: 0.11458 | J31: 0.466 | K31: 0.788 | L31: 0.7 | M31: 0.76 | N31: 1.05 | O31: 0.631 | P31: 0.67 | Q31: 0.7 | R31: 0.59 | S31: 0.72 | T31: 0.769 | U31: 0.86 | V31: 0.88 | W31: 0.49 | X31: 0.6 | Y31: 0.8 | Z31: 0.86 | AA31: 0.35 | AB31: 0.68 | AC31: 0.72 | AD31: 0.87 | AE31: 0.88 | AF31: 0.99 | AG31: 1.02 | AH31: 1.03 | AI31: 0 | BO31: 14.7137 | BP31: 15.23781 | BQ31: 15.3 | BR31: 15.03 | BS31: 15.03 | BT31: 15.68 | BU31: 15.5 | BV31: 15.5 | BW31: 15.96 | BX31: 15.96 | BY31: 16.14 | BZ31: 16.9 | CA31: 16.9 | CB31: 17.1 | CC31: 17.1 | CD31: 17.1 | CE31: 17.8 | CF31: 17.8 | CG31: 17.8 | CH31: 17.8 | CI31: 17.8 | CJ31: 17.8 | CK31: 17.8 | CL31: 17.8 | CM31: 17.8 | CN31: 17.8
D32: ORACLE-T8s | E32: ORACLE-ERPHRS02 | I32: 0.82088 | J32: 0.796 | K32: 1.13 | L32: 1.2 | M32: 0.48 | N32: 0.54 | O32: 0.506 | P32: 0.8 | Q32: 0.56 | R32: 0.82 | S32: 0.87 | T32: 0.888 | U32: 0.92 | V32: 1 | W32: 1.05 | X32: 0.35 | Y32: 0.74 | Z32: 0.84 | AA32: 1.02 | AB32: 1.05 | AC32: 0.9 | AD32: 1 | AE32: 1.01 | AF32: 1.02 | AG32: 1.04 | AH32: 1.15 | AI32: 1.22 | AJ32: 1.26 | AK32: 1.99 | BO32: 14.94874 | BP32: 14.94903 | BQ32: 14.9 | BR32: 15.32 | BS32: 15.43 | BT32: 15.8 | BU32: 15.63 | BV32: 15.78 | BW32: 15.78 | BX32: 15.78 | BY32: 15.95 | BZ32: 16.7 | CA32: 16.7 | CB32: 15.8 | CC32: 17.2 | CD32: 17.2 | CE32: 17.2 | CF32: 17.2 | CG32: 17.2 | CH32: 18.2 | CI32: 18.2 | CJ32: 18.2 | CK32: 18.2 | CL32: 18.2 | CM32: 18.2 | CN32: 18.2
D33: ORACLE-T8s | E33: ORACLE-ERPPRJ01 | I33: 0.91256 | J33: 0.98 | K33: 1.05 | L33: 1.06 | M33: 0.56 | N33: 0.82 | O33: 0.913 | P33: 0.79 | Q33: 0.91 | R33: 0.94 | S33: 0.96 | T33: 0.72 | U33: 1.05 | V33: 0.59 | W33: 0.92 | X33: 0.98 | Y33: 1.42 | Z33: 0.39 | AA33: 0.68 | AB33: 0.78 | AC33: 0.82 | AD33: 0.96 | AE33: 0.96 | AF33: 0.18 | AG33: 0.55 | AH33: 0.81 | AI33: 0.84 | AJ33: 0.95 | AK33: 0.15 | AL33: 0.2 | AM33: 0.52 | AN33: 0.56 | AO33: 0.62 | AP33: 0.67 | AQ33: 0.74 | AR33: 0.76 | AS33: 0.83 | AT33: 0.86 | AU33: 0.86 | AV33: 1 | AW33: 1.04 | AX33: 0.86 | AY33: 0.95 | AZ33: 1.19 | BA33: 1.24 | BB33: 1.33 | BC33: 0.04 | BD33: 0.75 | BE33: 0.8 | BF33: 0.86 | BG33: 1.1 | BH33: 1.12 | BI33: 0.63 | BJ33: 1.02 | BK33: 2.65 | BL33: 2.73 | BO33: 14.32524 | BP33: 14.32524 | BQ33: 14.3 | BR33: 15.32 | BS33: 15.32 | BT33: 15.66 | BU33: 15.32 | BV33: 15.32 | BW33: 15.32 | BX33: 15.32 | BY33: 16.57 | BZ33: 17.4 | CA33: 17.9 | CB33: 16.9 | CC33: 16.9 | CD33: 16.9 | CE33: 17.7 | CF33: 17.8 | CG33: 17.8 | CH33: 17.8 | CI33: 17.8 | CJ33: 17.8 | CK33: 17.8 | CL33: 18.8 | CM33: 18.8 | CN33: 18.8
D34: ORACLE-T8s | E34: ORACLE-ERPPRJ02 | I34: 0.82765 | J34: 0.861 | K34: 1.06 | L34: 1.08 | M34: 1.98 | N34: 0.71 | O34: 0.817 | P34: 0.05 | Q34: 0.99 | R34: 0.57 | S34: 0.75 | T34: 0.811 | U34: 0.86 | V34: 0.9 | W34: 0.97 | X34: 1.38 | Y34: 0.41 | Z34: 0.52 | AA34: 0.6 | AB34: 0.63 | AC34: 0.66 | AD34: 0.71 | AE34: 1.11 | AF34: 1.17 | AG34: 1.19 | AH34: 1.34 | AI34: 1.58 | AJ34: 1.62 | AK34: 0.14 | AL34: 0.2 | AM34: 0.21 | AN34: 0.56 | AO34: 0.61 | AP34: 0.73 | AQ34: 0.8 | AR34: 0.85 | AS34: 1 | AT34: 1 | AU34: 1 | AV34: 1.07 | AW34: 1.2 | AX34: 2.55 | AY34: 2.58 | AZ34: 2.61 | BA34: 2.61 | BB34: 0 | BC34: 0 | BD34: 0 | BE34: 0 | BF34: 0 | BG34: 0 | BH34: 0 | BI34: 0 | BJ34: 0 | BK34: 0.62 | BL34: 0.88 | BO34: 13.89231 | BP34: 13.8924 | BQ34: 13.8 | BR34: 15.36 | BS34: 15.36 | BT34: 15.7 | BU34: 15.36 | BV34: 12.31 | BW34: 16.01 | BX34: 16.01 | BY34: 16.18 | BZ34: 16.9 | CA34: 16.9 | CB34: 16.1 | CC34: 16 | CD34: 17.5 | CE34: 17.5 | CF34: 17.5 | CG34: 17.5 | CH34: 17.5 | CI34: 17.5 | CJ34: 17.6 | CK34: 17.6 | CL34: 17.7 | CM34: 17.7 | CN34: 17.7 | CO34: 17.7 | CP34: 17.7 | CQ34: 17.8 | CR34: 17.8 | CS34: 17.9
D35: ORACLE-T8s | E35: ORACLE-ERPRES01 (Commvault ERP test lun) | N35: 3.28 | O35: 3.51 | P35: 0.88 | Q35: 0.72 | R35: 0.85 | S35: 0.85 | T35: 0.845 | U35: 0.83 | V35: 0.05 | W35: 0.03 | X35: 0.04 | Y35: 0.04 | Z35: 0.39 | AA35: 0.85 | AB35: 1.61 | AC35: 1.87 | AD35: 0 | AE35: 0 | AF35: 0 | AG35: 0 | AH35: 0 | AI35: 0 | AJ35: 0 | AK35: 0 | AL35: 0 | AM35: 0 | AN35: 0 | AO35: 0 | AP35: 0 | AQ35: 0 | AR35: 0 | AS35: 0 | AT35: 0 | AU35: 0 | AV35: 0 | AW35: 0 | AX35: 0 | AY35: 0 | AZ35: 0 | BA35: 0 | BB35: 0 | BC35: 0 | BD35: 0 | BE35: 0 | BF35: 0 | BG35: 0 | BH35: 0 | BI35: 0 | BJ35: 0 | BK35: 0 | BL35: 0
D36: ORACLE-T8s | E36: ORACLE-ERPRIM01 | I36: 0.12765 | J36: 0.471 | K36: 0.68 | L36: 0.45 | M36: 0.37 | N36: 0.29 | O36: 0.593 | P36: 0.51 | Q36: 0.56 | R36: 0.39 | S36: 0.44 | T36: 0.453 | U36: 0.76 | V36: 0.8 | W36: 0.7 | X36: 0.35 | Y36: 0.37 | Z36: 0.39 | AA36: 0.38 | AB36: 0.41 | AC36: 0.38 | AD36: 0.24 | AE36: 1 | AF36: 0.73 | AG36: 0.8 | AH36: 0.46 | AI36: 0.43 | AJ36: 0.55 | AK36: 0.45 | AL36: 0.61 | AM36: 0.68 | AN36: 0.8 | AO36: 0.36 | AP36: 0.48 | AQ36: 0.49 | AR36: 0.99 | AS36: 1.01 | AT36: 0.92 | AU36: 0.92 | AV36: 0.82 | AW36: 0.68 | AX36: 0.55 | AY36: 0.56 | AZ36: 0.54 | BA36: 0.9 | BB36: 0.97 | BC36: 1.57 | BD36: 0.13 | BE36: 0.54 | BF36: 0.45 | BG36: 0.64 | BH36: 0.71 | BI36: 0.78 | BJ36: 0.74 | BK36: 0.74 | BL36: 1.07 | BO36: 14.81985 | BP36: 15.27437 | BQ36: 15.4 | BR36: 15.26 | BS36: 15.48 | BT36: 15.8 | BU36: 15.7 | BV36: 15.88 | BW36: 16.05 | BX36: 16.24 | BY36: 16.58 | BZ36: 17.7 | CA36: 17.8 | CB36: 17.1 | CC36: 17.4 | CD36: 17.5 | CE36: 17.7 | CF36: 17.9 | CG36: 17.9 | CH36: 18.3 | CI36: 18.3 | CJ36: 18.7 | CK36: 18.7 | CL36: 19.3 | CM36: 19.3 | CN36: 19.5 | CO36: 19.5 | CP36: 19.6 | CQ36: 19.7 | CR36: 19.8 | CS36: 19.8
D37: ORACLE-T8s | E37: ORACLE-ERPRIM02 | M37: 0 | N37: 0.14 | O37: 0.321 | P37: 0.33 | Q37: 0.44 | R37: 0.56 | S37: 0.56 | T37: 0.608 | U37: 0.61 | V37: 0.57 | W37: 0.67 | X37: 0.69 | Y37: 0.47 | Z37: 0.54 | AA37: 0.68 | AB37: 0.69 | AC37: 0.78 | AD37: 0.82 | AE37: 0.83 | AF37: 0.84 | AG37: 0.86 | AH37: 0.46 | AI37: 0.46 | AJ37: 0.38 | AK37: 0.31 | AL37: 0.45 | AM37: 0.57 | AN37: 0.69 | AO37: 0.73 | AP37: 0 | AQ37: 0 | AR37: 0 | AS37: 0 | AT37: 0 | AU37: 0 | AV37: 0 | AW37: 0 | AX37: 0 | AY37: 0 | AZ37: 0 | BA37: 0 | BB37: 0 | BC37: 0 | BD37: 0 | BE37: 0 | BF37: 0 | BG37: 0 | BH37: 0 | BI37: 0 | BJ37: 0 | BK37: 0 | BL37: 0 | BT37: 15.66 | BU37: 15.49 | BV37: 15.49 | BW37: 15.49 | BX37: 15.49 | BY37: 15.66 | BZ37: 16.4 | CA37: 17.8 | CB37: 16.9 | CC37: 16.8 | CD37: 17.4 | CE37: 17.4 | CF37: 17.4 | CG37: 17.4 | CH37: 17.4 | CI37: 17.4 | CJ37: 17.4 | CK37: 17.4 | CL37: 19.2 | CM37: 19.2 | CN37: 19.4 | CO37: 19.5 | CP37: 19.5 | CQ37: 19.5 | CR37: 19.5 | CS37: 19.6
D38: ORACLE-T8s | E38: ORACLE-ERPSBX01 | I38: 0.08015 | J38: 0.458 | K38: 0.45 | L38: 0.35 | M38: 0.35 | N38: 0.36 | O38: 0.393 | P38: 0.4 | Q38: 0.38 | R38: 0.41 | S38: 0.4 | T38: 0.521 | U38: 0.7 | V38: 0.55 | W38: 0.39 | X38: 0.31 | Y38: 0.4 | Z38: 0.39 | AA38: 0.43 | AB38: 0.43 | AC38: 0.42 | AD38: 0.53 | AE38: 0.5 | AF38: 0.54 | AG38: 0.62 | AH38: 0.49 | AI38: 0.4 | AJ38: 0.64 | AK38: 0.37 | AL38: 0.57 | AM38: 1.05 | AN38: 0.43 | AO38: 0.96 | AP38: 0.92 | AQ38: 0.58 | AR38: 0.89 | AS38: 0.89 | AT38: 0.07 | AU38: 0.07 | AV38: 0.2 | AW38: 0.43 | AX38: 0.7 | AY38: 0.52 | AZ38: 0.55 | BA38: 0.58 | BB38: 0.59 | BC38: 0.65 | BD38: 0.15 | BE38: 0.42 | BF38: 0.87 | BG38: 1.39 | BH38: 1.42 | BI38: 1.54 | BJ38: 1.46 | BK38: 1.36 | BL38: 1.38 | BO38: 14.83561 | BP38: 15.30703 | BQ38: 15.4 | BR38: 15.32 | BS38: 15.45 | BT38: 15.78 | BU38: 15.73 | BV38: 15.92 | BW38: 16.07 | BX38: 16.24 | BY38: 16.76 | BZ38: 17.6 | CA38: 17.9 | CB38: 17.1 | CC38: 17.4 | CD38: 17.5 | CE38: 17.7 | CF38: 17.9 | CG38: 17.9 | CH38: 17.9 | CI38: 17.9 | CJ38: 18.7 | CK38: 18.7 | CL38: 19.2 | CM38: 19.2 | CN38: 19.6 | CO38: 19.6 | CP38: 19.6 | CQ38: 19.6 | CR38: 19.6 | CS38: 19.6
D39: ORACLE-T8s | E39: ORACLE-ERPTST01 | AL39: 0 | AM39: 0.16 | AN39: 0.18 | AO39: 0.61 | AP39: 1.03 | AQ39: 0.71 | AR39: 0.78 | AS39: 1.03 | AT39: 1.31 | AU39: 1.31 | AV39: 0.35 | AW39: 0.74 | AX39: 0.83 | AY39: 0.89 | AZ39: 0.93 | BA39: 0.94 | BB39: 1.17 | BC39: 1.22 | BD39: 0 | BE39: 0 | BF39: 0 | BG39: 0 | BH39: 0 | BI39: 0 | BJ39: 0 | BK39: 0 | BL39: 0
D40: ORACLE-T8s | E40: ORACLE-ERPUAT01 | AW40: 0.7 | AX40: 0.83 | AY40: 0.56 | AZ40: 0.66 | BA40: 0.73 | BB40: 0.76 | BC40: 0.9 | BD40: 1.43 | BE40: 1 | BF40: 1.43 | BG40: 1.61 | BH40: 1.66 | BI40: 1.72 | BJ40: 1.63 | BK40: 1.52 | BL40: 1.55
D41: ORACLE-T8s | E41: ORACLE-NON-ERP-DEV | I41: 3.62 | J41: 3.79 | K41: 3.89 | L41: 3.93 | M41: 3.98 | N41: 3.99 | O41: 4.14 | P41: 2.67 | Q41: 2.54 | R41: 2.58 | S41: 2.39 | T41: 3.08 | U41: 4.24 | V41: 3.61 | W41: 2.86 | X41: 2.93 | Y41: 3.02 | Z41: 3.04 | AA41: 3.09 | AB41: 3.03 | AC41: 3.03 | AD41: 2.95 | AE41: 2.91 | AF41: 2.91 | AG41: 2.91 | AH41: 2.93 | AI41: 2.91 | AJ41: 2.93 | AK41: 3.03 | AL41: 2.48 | AM41: 2.52 | AN41: 2.53 | AO41: 2.22 | AP41: 2.16 | AQ41: 2.21 | AR41: 2.23 | AS41: 2.18 | AT41: 2.19 | AU41: 2.19 | AV41: 2.15 | AW41: 2.16 | AX41: 2.16 | AY41: 2.17 | AZ41: 2.16 | BA41: 2.14 | BB41: 2.15 | BC41: 2.11 | BD41: 2.1 | BE41: 2.1 | BF41: 2.08 | BG41: 2.05 | BH41: 2.04 | BI41: 2.03 | BJ41: 1.69 | BK41: 1.71 | BL41: 1.71 | BO41: 8.1 | BP41: 7.8 | BQ41: 7.8 | BR41: 7.8 | BS41: 7.8 | BT41: 8.4 | BU41: 8.4 | BV41: 8.4 | BW41: 8.14 | BX41: 8.14 | BY41: 9.99 | BZ41: 10.1 | CA41: 10.1 | CB41: 7.9 | CC41: 7.9 | CD41: 7.9 | CE41: 12.2 | CF41: 12.2 | CG41: 12.2 | CH41: 12.2 | CI41: 12.2 | CJ41: 7.9 | CK41: 7.9 | CL41: 7.9 | CM41: 7.9 | CN41: 7.9 | CO41: 7.9 | CP41: 7.9 | CQ41: 7.9 | CR41: 7.9 | CS41: 7.9
D42: ORACLE-T7s | E42: ORACLE-NON-ERP-DR01 | I42: 0.30237 | J42: 0.274 | K42: 0.29 | L42: 0.29 | M42: 0.28 | N42: 0.3 | O42: 0.292 | P42: 0.27 | Q42: 0.26 | R42: 0.26 | S42: 0.26 | T42: 0.306 | U42: 0.32 | V42: 0.29 | W42: 0.26 | X42: 0.27 | Y42: 0.29 | Z42: 0.29 | AA42: 0.3 | AB42: 0.3 | AC42: 0.3 | AD42: 0.3 | AE42: 0.3 | AF42: 0.3 | AG42: 0.3 | AH42: 0.3 | AI42: 0.31 | AJ42: 0.3 | AK42: 0.32 | AL42: 0.33 | AM42: 0.3 | AN42: 0.32 | AO42: 0.3 | AP42: 0.3 | AQ42: 0.31 | AR42: 0.32 | AS42: 0.34 | AT42: 0.33 | AU42: 0.33 | AV42: 0.32 | AW42: 0.31 | AX42: 0.31 | AY42: 0.31 | AZ42: 0.31 | BA42: 0.32 | BB42: 0.31 | BC42: 0.31 | BD42: 0.29 | BE42: 0.28 | BF42: 0.29 | BG42: 0.32 | BH42: 0.38 | BI42: 0.39 | BJ42: 0.35 | BK42: 0.32 | BL42: 0.31 | BO42: 4.7 | BP42: 4.7 | BQ42: 4.7 | BR42: 4.7 | BS42: 4.87 | BT42: 0.31 | BU42: 0.3 | BV42: 0.3 | BW42: 0.3 | BX42: 0.3 | BY42: 0.3 | BZ42: 0.5 | CA42: 0.3 | CB42: 0.5 | CC42: 0.3 | CD42: 0.2 | CE42: 0.2 | CF42: 0.2 | CG42: 0.2 | CH42: 0.2 | CI42: 0.2 | CJ42: 0.2 | CK42: 0.2 | CL42: 0.2 | CM42: 0.2 | CN42: 0.2 | CO42: 0.2 | CP42: 0.2 | CQ42: 0.2 | CR42: 0.2 | CS42: 0.2
D43: ORACLE-T7s | E43: ORACLE-NON-ERP-DR02 | I43: 1.93 | J43: 2.04 | K43: 2.22 | L43: 2.25 | M43: 2.34 | N43: 2.35 | O43: 1.96 | P43: 1.33 | Q43: 1.31 | R43: 1.28 | S43: 1.31 | T43: 1.33 | U43: 2.4 | V43: 1.92 | W43: 1.69 | X43: 1.73 | Y43: 1.81 | Z43: 1.34 | AA43: 1.36 | AB43: 1.37 | AC43: 0.95 | AD43: 2.03 | AE43: 2.03 | AF43: 2.03 | AG43: 2.03 | AH43: 2.06 | AI43: 2.06 | AJ43: 2.07 | AK43: 2 | AL43: 1.65 | AM43: 1.6 | AN43: 1.6 | AO43: 1.69 | AP43: 1.61 | AQ43: 1.72 | AR43: 1.78 | AS43: 1.83 | AT43: 1.86 | AU43: 1.86 | AV43: 1.82 | AW43: 1.87 | AX43: 1.9 | AY43: 1.91 | AZ43: 1.91 | BA43: 1.92 | BB43: 1.94 | BC43: 1.95 | BD43: 1.98 | BE43: 2 | BF43: 2 | BG43: 2 | BH43: 2 | BI43: 2.02 | BJ43: 1.73 | BK43: 1.65 | BL43: 1.64 | BO43: 4.7 | BP43: 4.7 | BQ43: 4.7 | BR43: 4.7 | BS43: 4.9 | BT43: 1.6 | BU43: 1.6 | BV43: 1.6 | BW43: 1.6 | BX43: 1.6 | BY43: 1.73 | BZ43: 1.8 | CA43: 1.9 | CB43: 1.9 | CC43: 1.8 | CD43: 1.9 | CE43: 1.9 | CF43: 1.9 | CG43: 1.9 | CH43: 2 | CI43: 2 | CJ43: 2 | CK43: 2 | CL43: 2.1 | CM43: 2.1 | CN43: 2.1 | CO43: 2.1 | CP43: 2.1 | CQ43: 2.1 | CR43: 2.1 | CS43: 2.1
D44: ORACLE-T7s | E44: ORACLE-T74-OS-APP | J44: 0.716 | K44: 0.75 | L44: 0.77 | M44: 0.79 | N44: 0.74 | O44: 0.765 | P44: 0.63 | Q44: 0.65 | R44: 0.67 | S44: 0.69 | T44: 0.707 | U44: 0.71 | V44: 0.74 | W44: 0.73 | X44: 0.75 | Y44: 0.78 | Z44: 0.78 | AA44: 0.8 | AB44: 0.8 | AC44: 0.82 | AD44: 0.81 | AE44: 0.82 | AF44: 0.82 | AG44: 0.83 | AH44: 0.84 | AI44: 0.85 | AJ44: 0.86 | AK44: 0.87 | AL44: 0.88 | AM44: 0.86 | AN44: 0.86 | AO44: 0.88 | AP44: 0.86 | AQ44: 0.87 | AR44: 0.88 | AS44: 0.88 | AT44: 0.89 | AU44: 0.89 | AV44: 0.85 | AW44: 0.85 | AX44: 0.86 | AY44: 0.86 | AZ44: 0.86 | BA44: 0.86 | BB44: 0.86 | BC44: 0.87 | BD44: 0.87 | BE44: 0.88 | BF44: 0.88 | BG44: 0.87 | BH44: 0.87 | BI44: 0.87 | BJ44: 0.74 | BK44: 0.69 | BL44: 0.68 | BO44: 7.4 | BP44: 7.4 | BV44: 7.3 | BW44: 7.3 | BX44: 7.3 | BY44: 7.3
...

Sheet EQUINIX DC
A1: Equinix (12% YoY) | B1: Total Storage | C1: Month | D1: In Use | E1: Change (TB) | F1: Growth (%) | G1: Forecast | H1: In use (%) | I1: Forecast (%) | J1: Max % | AZ1: Aug'25
A2: X20+M20 | B2: =('Data Collection Sheet'!$G$92+'Data Collection Sheet'!$G$100)-35.5+17.2 -> 45.86 | C2: 44562 | D2: ='Data Collection Sheet'!I91+'Data Collection Sheet'!I99 -> 8.90968 | H2: =(D2/B2)*100 -> 19.427998 | J2: 90
B3: =('Data Collection Sheet'!$G$92+'Data Collection Sheet'!$G$100)-35.5+17.2 -> 45.86 | C3: 44593 | D3: ='Data Collection Sheet'!J91+'Data Collection Sheet'!J99 -> 9.867 | H3: =(D3/B3)*100 -> 21.515482 | J3: 90
A4: NR Complete Migration (8.8TB migrated) | B4: =('Data Collection Sheet'!$G$92+'Data Collection Sheet'!$G$100)-35.5+17.2 -> 45.86 | C4: 44621 | D4: =SUM('Data Collection Sheet'!K91+'Data Collection Sheet'!K99) -> 18.677 | H4: =(D4/B4)*100 -> 40.726123 | J4: 90
A5: Stabilized Data | B5: =('Data Collection Sheet'!$G$92+'Data Collection Sheet'!$G$100)-35.5+17.2 -> 45.86 | C5: 44652 | D5: =SUM('Data Collection Sheet'!L91+'Data Collection Sheet'!L99) -> 18.04 | H5: =(D5/B5)*100 -> 39.337113 | J5: 90
A6: Order uplift to 35TB | B6: =('Data Collection Sheet'!$G$92+'Data Collection Sheet'!$G$100)-35.5+17.2 -> 45.86 | C6: 44682 | D6: =SUM('Data Collection Sheet'!M91+'Data Collection Sheet'!M99) -> 18.23 | H6: =(D6/B6)*100 -> 39.751417 | J6: 90
B7: =('Data Collection Sheet'!$G$92+'Data Collection Sheet'!$G$100)-35.5+17.2 -> 45.86 | C7: 44713 | D7: =SUM('Data Collection Sheet'!N91+'Data Collection Sheet'!N99) -> 18.55 | H7: =(D7/B7)*100 -> 40.449193 | J7: 90
B8: =('Data Collection Sheet'!$G$92+'Data Collection Sheet'!$G$100)-35.5+17.2 -> 45.86 | C8: 44743 | D8: =SUM('Data Collection Sheet'!O91+'Data Collection Sheet'!O99) -> 19.035 | H8: =(D8/B8)*100 -> 41.50676 | J8: 90
B9: =('Data Collection Sheet'!$G$92+'Data Collection Sheet'!$G$100)-35.5+17.2 -> 45.86 | C9: 44774 | D9: =SUM('Data Collection Sheet'!P91+'Data Collection Sheet'!P99) -> 19.16 | H9: =(D9/B9)*100 -> 41.779328 | J9: 90 | AZ9: Aug'25
A10: Implement X20 uplift to 35TB | B10: =('Data Collection Sheet'!G92+'Data Collection Sheet'!G100) -> 64.16 | C10: 44805 | D10: =SUM('Data Collection Sheet'!Q91+'Data Collection Sheet'!Q99) -> 20.215 | H10: =(D10/B10)*100 -> 31.50717 | J10: 90 | AZ10: 8.77
A11: Renew maintenace M20 till Nov 24 | B11: =35.5+'Data Collection Sheet'!$G$100 -> 48.21 | C11: 44835 | D11: =SUM('Data Collection Sheet'!R91+'Data Collection Sheet'!R99) -> 20.81 | H11: =(D11/B11)*100 -> 43.165318 | J11: 90 | AZ11: 1.49
B12: =35.5+'Data Collection Sheet'!$G$100 -> 48.21 | C12: 44866 | D12: =SUM('Data Collection Sheet'!S91+'Data Collection Sheet'!S99) -> 20.92 | H12: =(D12/B12)*100 -> 43.393487 | J12: 90 | AZ12: 0.06
B13: =35.5+'Data Collection Sheet'!$G$100 -> 48.21 | C13: 44896 | D13: =SUM('Data Collection Sheet'!T91+'Data Collection Sheet'!T99) -> 21.35 | H13: =(D13/B13)*100 -> 44.285418 | J13: 90 | AZ13: 25.94
B14: =35.5+'Data Collection Sheet'!$G$100 -> 48.21 | C14: 44927 | D14: =SUM('Data Collection Sheet'!U91+'Data Collection Sheet'!U99) -> 21.48 | H14: =(D14/B14)*100 -> 44.555072 | J14: 90 | AZ14: 0.23
B15: =35.5+'Data Collection Sheet'!$G$100 -> 48.21 | C15: 44958 | D15: =SUM('Data Collection Sheet'!V91+'Data Collection Sheet'!V99) -> 21.49 | H15: =(D15/B15)*100 -> 44.575814 | J15: 90 | AZ15: 0.49
B16: =35.5+'Data Collection Sheet'!$G$100 -> 48.21 | C16: 44986 | D16: =SUM('Data Collection Sheet'!W91+'Data Collection Sheet'!W99) -> 21.84 | H16: =(D16/B16)*100 -> 45.301805 | J16: 90 | AZ16: 0.3
B17: =35.5+'Data Collection Sheet'!$G$100 -> 48.21 | C17: 45017 | D17: =SUM('Data Collection Sheet'!X91+'Data Collection Sheet'!X99) -> 22.05 | H17: =(D17/B17)*100 -> 45.737399 | J17: 90 | AZ17: 0
B18: =35.5+'Data Collection Sheet'!$G$100 -> 48.21 | C18: 45047 | D18: =SUM('Data Collection Sheet'!Y91+'Data Collection Sheet'!Y99) -> 22.48 | H18: =(D18/B18)*100 -> 46.62933 | J18: 90 | AZ18: 0
B19: =35.5+'Data Collection Sheet'!$G$100 -> 48.21 | C19: 45078 | D19: =SUM('Data Collection Sheet'!Z91+'Data Collection Sheet'!Z99) -> 22.36 | H19: =(D19/B19)*100 -> 46.380419 | J19: 90 | AZ19: 0
B20: =35.5+'Data Collection Sheet'!$G$100 -> 48.21 | C20: 45108 | D20: =SUM('Data Collection Sheet'!AA91+'Data Collection Sheet'!AA99) -> 22.59 | H20: =(D20/B20)*100 -> 46.857498 | J20: 90 | AZ20: 0
B21: =35.5+'Data Collection Sheet'!$G$100 -> 48.21 | C21: 45139 | D21: =SUM('Data Collection Sheet'!AB91+'Data Collection Sheet'!AB99) -> 22.84 | E21: 0 | H21: =(D21/B21)*100 -> 47.376063 | J21: 90
B22: =35.5+'Data Collection Sheet'!$G$100 -> 48.21 | C22: 45170 | D22: =SUM('Data Collection Sheet'!AC91+'Data Collection Sheet'!AC99) -> 21.06 | H22: =(D22/B22)*100 -> 43.683883 | J22: 90 | AZ22: 3.39
A23: Remove M20- supported till Nov-23 (13TB) | B23: =35.5+'Data Collection Sheet'!$G$100 -> 48.21 | C23: 45200 | D23: =SUM('Data Collection Sheet'!AD91+'Data Collection Sheet'!AD99) -> 21.29 | H23: =(D23/B23)*100 -> 44.160962 | J23: 90 | AZ23: 0.01
B24: 35 | C24: 45231 | D24: =SUM('Data Collection Sheet'!AE91+'Data Collection Sheet'!AE99) -> 21.91 | H24: =(D24/B24)*100 -> 62.6 | J24: 90
B25: 35 | C25: 45261 | D25: =SUM('Data Collection Sheet'!AF91+'Data Collection Sheet'!AF99) -> 21.92 | H25: =(D25/B25)*100 -> 62.628571 | J25: 90
B26: 35 | C26: 45292 | D26: =SUM('Data Collection Sheet'!AG91+'Data Collection Sheet'!AG99) -> 22 | H26: =(D26/B26)*100 -> 62.857143 | J26: 90
B27: 35 | C27: 45323 | D27: =SUM('Data Collection Sheet'!AH91+'Data Collection Sheet'!AH99) -> 22.37 | H27: =(D27/B27)*100 -> 63.914286 | J27: 90
B28: 35 | C28: 45352 | D28: =SUM('Data Collection Sheet'!AI91+'Data Collection Sheet'!AI99) -> 23.24 | H28: =(D28/B28)*100 -> 66.4 | J28: 90 | AY28: 1.14 | AZ28: 1.17
A29: Added more capacity with CR38226 (16TB) | B29: ='Data Collection Sheet'!$G$92 -> 51.45 | C29: 45383 | D29: =SUM('Data Collection Sheet'!AJ91+'Data Collection Sheet'!AJ99) -> 24.16 | H29: =(D29/B29)*100 -> 46.958212 | J29: 90 | AZ29: 0.37
A30: WChill DB 2 SQL - 1 Env. 15TB > 5TB on disk | B30: ='Data Collection Sheet'!$G$92 -> 51.45 | C30: 45413 | D30: =SUM('Data Collection Sheet'!AK91+'Data Collection Sheet'!AK99) -> 24.58 | E30: 9 | H30: =(D30/B30)*100 -> 47.774538 | J30: 90 | AZ30: 0.43
B31: ='Data Collection Sheet'!$G$92 -> 51.45 | C31: 45444 | D31: =SUM('Data Collection Sheet'!AL91+'Data Collection Sheet'!AL99) -> 33.12 | H31: =(D31/B31)*100 -> 64.373178 | J31: 90
B32: ='Data Collection Sheet'!$G$92 -> 51.45 | C32: 45474 | D32: =SUM('Data Collection Sheet'!AM91+'Data Collection Sheet'!AM99) -> 34.02 | H32: =(D32/B32)*100 -> 66.122449 | J32: 90
B33: ='Data Collection Sheet'!$G$92 -> 51.45 | C33: 45505 | D33: =SUM('Data Collection Sheet'!AN91+'Data Collection Sheet'!AN99) -> 33.86 | H33: =(D33/B33)*100 -> 65.811467 | J33: 90 | AZ33: 1.19
B34: ='Data Collection Sheet'!$G$92 -> 51.45 | C34: 45536 | D34: =SUM('Data Collection Sheet'!AO91+'Data Collection Sheet'!AO99) -> 34.3 | H34: =(D34/B34)*100 -> 66.666667 | J34: 90 | AZ34: 2.61
B35: ='Data Collection Sheet'!$G$92 -> 51.45 | C35: 45566 | D35: =SUM('Data Collection Sheet'!AP91+'Data Collection Sheet'!AP99) -> 34.79 | H35: =(D35/B35)*100 -> 67.619048 | J35: 90 | AZ35: 0
B36: ='Data Collection Sheet'!$G$92 -> 51.45 | C36: 45597 | D36: =SUM('Data Collection Sheet'!AQ91+'Data Collection Sheet'!AQ99) -> 35.23 | H36: =(D36/B36)*100 -> 68.474247 | J36: 90 | AZ36: 0.54
A37: Remove the Oracle Windchill RAC | B37: ='Data Collection Sheet'!$G$92 -> 51.45 | C37: 45627 | D37: =SUM('Data Collection Sheet'!AR91+'Data Collection Sheet'!AR99) -> 24.05 | H37: =(D37/B37)*100 -> 46.744412 | J37: 90 | AZ37: 0
B38: ='Data Collection Sheet'!$G$92 -> 51.45 | C38: 45658 | D38: =SUM('Data Collection Sheet'!AS91+'Data Collection Sheet'!AS99) -> 27.91 | H38: =(D38/B38)*100 -> 54.246842 | J38: 90 | AZ38: 0.55
B39: ='Data Collection Sheet'!$G$92 -> 51.45 | C39: 45689 | D39: =SUM('Data Collection Sheet'!AT91+'Data Collection Sheet'!AT99) -> 26.56 | H39: =(D39/B39)*100 -> 51.622935 | J39: 90 | AZ39: 0.93
B40: ='Data Collection Sheet'!$G$92 -> 51.45 | C40: 45717 | D40: =SUM('Data Collection Sheet'!AU91+'Data Collection Sheet'!AU99) -> 26.56 | H40: =(D40/B40)*100 -> 51.622935 | J40: 90 | AZ40: 0.66
...

Sheet MacPark-DC
A1: MacPark (12% YoY) | B1: Total Storage | C1: Month | D1: In Use | E1: Change (TB) | F1: Growth (%) | G1: Forecast | H1: In use (%) | I1: Forecast (%) | J1: Max %
A2: X50+M20+M20 | B2: =('Data Collection Sheet'!G25+'Data Collection Sheet'!G55) -> 130.5 | C2: 44562 | D2: =('Data Collection Sheet'!I24+'Data Collection Sheet'!I54) -> 103.7358 | H2: =(D2/B2)*100 -> 79.491034 | J2: 90
B3: 128.24 | C3: 44593 | D3: =('Data Collection Sheet'!J24+'Data Collection Sheet'!J54) -> 100.557 | H3: =(D3/B3)*100 -> 78.413132 | J3: 90
B4: 128.24 | C4: 44621 | D4: =('Data Collection Sheet'!K24+'Data Collection Sheet'!K54) -> 112.279 | H4: =(D4/B4)*100 -> 87.553805 | J4: 90
A5: Added NR M20 | B5: =('Data Collection Sheet'!G25+'Data Collection Sheet'!G55+'Data Collection Sheet'!G69) -> 168.05 | C5: 44652 | D5: ='Data Collection Sheet'!L24+'Data Collection Sheet'!L54+'Data Collection Sheet'!L68 -> 112.96 | H5: =(D5/B5)*100 -> 67.21809 | J5: 90
A6: Add Rimini ENV | B6: 165.09 | C6: 44682 | D6: ='Data Collection Sheet'!M24+'Data Collection Sheet'!M54+'Data Collection Sheet'!M68 -> 111.12 | E6: 1 | H6: =(D6/B6)*100 -> 67.308741 | J6: 90
B7: 165.09 | C7: 44713 | D7: ='Data Collection Sheet'!N24+'Data Collection Sheet'!N54+'Data Collection Sheet'!N68 -> 110.54 | H7: =(D7/B7)*100 -> 66.957417 | J7: 90
B8: 165.09 | C8: 44743 | D8: ='Data Collection Sheet'!O24+'Data Collection Sheet'!O54+'Data Collection Sheet'!O68 -> 111.552 | H8: =(D8/B8)*100 -> 67.570416 | J8: 90
A9: Removed staging Marketing Folder | B9: 165.09 | C9: 44774 | D9: ='Data Collection Sheet'!P24+'Data Collection Sheet'!P54+'Data Collection Sheet'!P68 -> 92.25 | H9: =(D9/B9)*100 -> 55.878612 | J9: 90
B10: 165.09 | C10: 44805 | D10: ='Data Collection Sheet'!Q24+'Data Collection Sheet'!Q54+'Data Collection Sheet'!Q68 -> 93.39 | H10: =(D10/B10)*100 -> 56.569144 | J10: 90
B11: 165.09 | C11: 44835 | D11: ='Data Collection Sheet'!R24+'Data Collection Sheet'!R54+'Data Collection Sheet'!R68 -> 95.46 | H11: =(D11/B11)*100 -> 57.823006 | J11: 90
A12: Migrate VNX - data1/MFG 10TB - Done | B12: 165.09 | C12: 44866 | D12: ='Data Collection Sheet'!S24+'Data Collection Sheet'!S54+'Data Collection Sheet'!S68 -> 98.65 | H12: =(D12/B12)*100 -> 59.755285 | J12: 90
A13: Migrate VNX - data2/Marketing 15TB - sync 99% | B13: 165.09 | C13: 44896 | D13: ='Data Collection Sheet'!T24+'Data Collection Sheet'!T54+'Data Collection Sheet'!T68 -> 115.8906 | H13: =(D13/B13)*100 -> 70.198437 | J13: 90
B14: 165.09 | C14: 44927 | D14: ='Data Collection Sheet'!U24+'Data Collection Sheet'!U54+'Data Collection Sheet'!U68 -> 119.8 | H14: =(D14/B14)*100 -> 72.566479 | J14: 90
A15: Migrate VNX - data2/Marketing 15TB - Done | B15: 165.09 | C15: 44958 | D15: ='Data Collection Sheet'!V24+'Data Collection Sheet'!V54+'Data Collection Sheet'!V68 -> 128.9 | H15: =(D15/B15)*100 -> 78.078624 | J15: 90
B16: 165.09 | C16: 44986 | D16: ='Data Collection Sheet'!W24+'Data Collection Sheet'!W54+'Data Collection Sheet'!W68 -> 126.29 | H16: =(D16/B16)*100 -> 76.497668 | J16: 90
B17: 165.09 | C17: 45017 | D17: ='Data Collection Sheet'!X24+'Data Collection Sheet'!X54+'Data Collection Sheet'!X68 -> 126.98 | H17: =(D17/B17)*100 -> 76.915622 | J17: 90
A18: Remove EV Servers since re-hydration completed, -10TB - Done | B18: 165.09 | C18: 45047 | D18: ='Data Collection Sheet'!Y24+'Data Collection Sheet'!Y54+'Data Collection Sheet'!Y68 -> 109.42 | H18: =(D18/B18)*100 -> 66.278999 | J18: 90
B19: 165.09 | C19: 45078 | D19: ='Data Collection Sheet'!Z24+'Data Collection Sheet'!Z54+'Data Collection Sheet'!Z68 -> 109.268 | H19: =(D19/B19)*100 -> 66.186928 | J19: 90
B20: 165.09 | C20: 45108 | D20: ='Data Collection Sheet'!AA24+'Data Collection Sheet'!AA54+'Data Collection Sheet'!AA68 -> 111.39 | H20: =(D20/B20)*100 -> 67.472288 | J20: 90
B21: 165.09 | C21: 45139 | D21: ='Data Collection Sheet'!AB24+'Data Collection Sheet'!AB54+'Data Collection Sheet'!AB68 -> 113.54 | H21: =(D21/B21)*100 -> 68.774608 | J21: 90
B22: 165.09 | C22: 45170 | D22: ='Data Collection Sheet'!AC24+'Data Collection Sheet'!AC54+'Data Collection Sheet'!AC68 -> 114.47 | H22: =(D22/B22)*100 -> 69.337937 | J22: 90
B23: 165.1 | C23: 45200 | D23: ='Data Collection Sheet'!AD24+'Data Collection Sheet'!AD54+'Data Collection Sheet'!AD68 -> 114.53 | H23: =(D23/B23)*100 -> 69.370079 | J23: 90
B24: 165.1 | C24: 45231 | D24: ='Data Collection Sheet'!AE24+'Data Collection Sheet'!AE54+'Data Collection Sheet'!AE68 -> 117.82 | H24: =(D24/B24)*100 -> 71.36281 | J24: 90
B25: 165.1 | C25: 45261 | D25: ='Data Collection Sheet'!AF24+'Data Collection Sheet'!AF54+'Data Collection Sheet'!AF68 -> 123.89 | H25: =(D25/B25)*100 -> 75.03937 | J25: 90
B26: 165.1 | C26: 45292 | D26: ='Data Collection Sheet'!AG24+'Data Collection Sheet'!AG54+'Data Collection Sheet'!AG68 -> 125.96 | H26: =(D26/B26)*100 -> 76.293156 | J26: 90
A27: Move aun-nbm-prd01 & coh-srv-nbm01 to MacPark | B27: 165.1 | C27: 45323 | D27: ='Data Collection Sheet'!AH24+'Data Collection Sheet'!AH54+'Data Collection Sheet'!AH68 -> 126.26 | E27: 1 | H27: =(D27/B27)*100 -> 76.474864 | J27: 90
A28: Windchill 45TB front-end (3-DEV Env. each 9,3 TB on disk) (assum 1,6 compressed) | B28: 165.1 | C28: 45352 | D28: ='Data Collection Sheet'!AI24+'Data Collection Sheet'!AI54+'Data Collection Sheet'!AI68 -> 123.43 | E28: 9 | H28: =(D28/B28)*100 -> 74.760751 | J28: 90
B29: 165.1 | C29: 45383 | D29: ='Data Collection Sheet'!AJ24+'Data Collection Sheet'!AJ54+'Data Collection Sheet'!AJ68 -> 125.36 | H29: =(D29/B29)*100 -> 75.92974 | J29: 90
A30: Refreshed BIEUAT01 env and additional 2TB required | B30: 165.1 | C30: 45413 | D30: ='Data Collection Sheet'!AK24+'Data Collection Sheet'!AK54+'Data Collection Sheet'!AK68 -> 123.05 | H30: =(D30/B30)*100 -> 74.530588 | J30: 90
A31: Move AUM-FPS-PRD03 from aum-pc-prd02 to aum-pc-prd03. New ERPTST01 env with snapclone. Windchill DR env after re-vaulting. | B31: 165.1 | C31: 45444 | D31: ='Data Collection Sheet'!AL24+'Data Collection Sheet'!AL54+'Data Collection Sheet'!AL68 -> 131.27 | H31: =(D31/B31)*100 -> 79.509388 | J31: 90
B32: 165.1 | C32: 45474 | D32: ='Data Collection Sheet'!AM24+'Data Collection Sheet'!AM54+'Data Collection Sheet'!AM68 -> 131.82 | H32: =(D32/B32)*100 -> 79.84252 | J32: 90
B33: 165.1 | C33: 45505 | D33: ='Data Collection Sheet'!AN24+'Data Collection Sheet'!AN54+'Data Collection Sheet'!AN68 -> 132.93 | H33: =(D33/B33)*100 -> 80.514839 | J33: 90
B34: 165.1 | C34: 45536 | D34: ='Data Collection Sheet'!AO24+'Data Collection Sheet'!AO54+'Data Collection Sheet'!AO68 -> 136.16 | H34: =(D34/B34)*100 -> 82.47123 | J34: 90
B35: 165.1 | C35: 45566 | D35: ='Data Collection Sheet'!AP24+'Data Collection Sheet'!AP54+'Data Collection Sheet'!AP68 -> 123.09 | H35: =(D35/B35)*100 -> 74.554815 | J35: 90
B36: 165.1 | C36: 45597 | D36: ='Data Collection Sheet'!AQ24+'Data Collection Sheet'!AQ54+'Data Collection Sheet'!AQ68 -> 123.34 | H36: =(D36/B36)*100 -> 74.706239 | J36: 90
B37: 165.1 | C37: 45627 | D37: ='Data Collection Sheet'!AR24+'Data Collection Sheet'!AR54+'Data Collection Sheet'!AR68 -> 126.76 | H37: =(D37/B37)*100 -> 76.77771 | J37: 90
B38: 165.1 | C38: 45658 | D38: ='Data Collection Sheet'!AS24+'Data Collection Sheet'!AS54+'Data Collection Sheet'!AS68 -> 130.37 | H38: =(D38/B38)*100 -> 78.964264 | J38: 90
B39: 165.1 | C39: 45689 | D39: ='Data Collection Sheet'!AT24+'Data Collection Sheet'!AT54+'Data Collection Sheet'!AT68 -> 128.59 | H39: =(D39/B39)*100 -> 77.88613 | J39: 90
B40: 165.1 | C40: 45717 | D40: ='Data Collection Sheet'!AU24+'Data Collection Sheet'!AU54+'Data Collection Sheet'!AU68 -> 128.59 | H40: =(D40/B40)*100 -> 77.88613 | J40: 90
...

Sheet Denver (Unity)
A1: Denver (12% YoY) | B1: Total Storage | C1: Month | D1: In Use | E1: Change (TB) | F1: Growth (%) | G1: Forecast | H1: In use (%) | I1: Forecast (%) | J1: Max %
A2: USD-UNITY-PRD01 POOL1 | B2: 25.7 | C2: 45292 | D2: 14.15 | H2: =(D2/B2)*100 -> 55.058366 | J2: 90
B3: 25.7 | C3: 45323 | D3: 14.2 | H3: =(D3/B3)*100 -> 55.252918 | J3: 90
B4: 25.7 | C4: 45352 | D4: 14.2 | H4: =(D4/B4)*100 -> 55.252918 | J4: 90
B5: 25.7 | C5: 45383 | D5: 14.6 | H5: =(D5/B5)*100 -> 56.809339 | J5: 90
B6: 25.7 | C6: 45413 | D6: 14.4 | H6: =(D6/B6)*100 -> 56.031128 | J6: 90
B7: 25.7 | C7: 45444 | D7: 14.6 | H7: =(D7/B7)*100 -> 56.809339 | J7: 90
B8: 25.7 | C8: 45474 | D8: 15 | H8: =(D8/B8)*100 -> 58.365759 | J8: 90
B9: 25.7 | C9: 45505 | D9: 15.1 | H9: =(D9/B9)*100 -> 58.754864 | J9: 90
B10: 25.7 | C10: 45536 | D10: 15.2 | H10: =(D10/B10)*100 -> 59.143969 | J10: 90
B11: 25.7 | C11: 45566 | D11: 15.2 | H11: =(D11/B11)*100 -> 59.143969 | J11: 90
B12: 25.7 | C12: 45597 | D12: 15.3 | H12: =(D12/B12)*100 -> 59.533074 | J12: 90
B13: 25.7 | C13: 45627 | D13: 15.3 | H13: =(D13/B13)*100 -> 59.533074 | J13: 90
B14: 25.7 | C14: 45658 | D14: 15.4 | H14: =(D14/B14)*100 -> 59.922179 | J14: 90
... B25: 25.7 | C25: 45992 | D25: 16.2 | H25: =(D25/B25)*100 -> 63.035019 | J25: 90
A26: Move 7TB FileServices to AWS or HQ | B26: 25.7 | C26: 46023 | D26: 16.2 | H26: =(D26/B26)*100 -> 63.035019 | J26: 90
B27: 25.7 | C27: 46054 | D27: 16.2 | H27: =(D27/B27)*100 -> 63.035019 | J27: 90
B28: 25.7 | C28: 46082 | D28: 16.2 | H28: =(D28/B28)*100 -> 63.035019 | J28: 90
B29: 25.7 | C29: 46113 | D29: 16.2 | H29: =(D29/B29)*100 -> 63.035019 | J29: 90
B30: 25.7 | C30: 46143 | D30: 16.2 | H30: =(D30/B30)*100 -> 63.035019 | J30: 90
B31: 25.7 | C31: 46174 | D31: 16.2 | H31: =(D31/B31)*100 -> 63.035019 | J31: 90
B32: 25.7 | C32: 46204 | D32: 16.3 | H32: =(D32/B32)*100 -> 63.424125 | J32: 90
B33: 25.7 | C33: 46235 | D33: 16.3 | F33: 1.08 | G33: =D33 -> 16.3 | H33: =(D33/B33)*100 -> 63.424125 | I33: =(G33/B33)*100 -> 63.424125 | J33: 90
B34: 25.7 | C34: 46266 | F34: 1.08 | G34: =G33*(1+(F34^(1/12)-1))+E34 -> 16.404875 | I34: =(G34/B34)*100 -> 63.832197 | J34: 90
B35: 25.7 | C35: 46296 | F35: 1.08 | G35: =G34*(1+(F35^(1/12)-1))+E35 -> 16.510424 | I35: =(G35/B35)*100 -> 64.242896 | J35: 90
B36: 25.7 | C36: 46327 | F36: 1.08 | G36: =G35*(1+(F36^(1/12)-1))+E36 -> 16.616653 | I36: =(G36/B36)*100 -> 64.656236 | J36: 90
B37: 25.7 | C37: 46357 | F37: 1.08 | G37: =G36*(1+(F37^(1/12)-1))+E37 -> 16.723565 | I37: =(G37/B37)*100 -> 65.072236 | J37: 90
B38: 25.7 | C38: 46388 | F38: 1.08 | G38: =G37*(1+(F38^(1/12)-1))+E38 -> 16.831165 | I38: =(G38/B38)*100 -> 65.490913 | J38: 90
B39: 25.7 | C39: 46419 | F39: 1.08 | G39: =G38*(1+(F39^(1/12)-1))+E39 -> 16.939457 | I39: =(G39/B39)*100 -> 65.912284 | J39: 90
B40: 25.7 | C40: 46447 | F40: 1.08 | G40: =G39*(1+(F40^(1/12)-1))+E40 -> 17.048446 | I40: =(G40/B40)*100 -> 66.336365 | J40: 90
B41: 25.7 | C41: 46478 | F41: 1.08 | G41: =G40*(1+(F41^(1/12)-1))+E41 -> 17.158136 | I41: =(G41/B41)*100 -> 66.763175 | J41: 90
B42: 25.7 | C42: 46508 | F42: 1.08 | G42: =G41*(1+(F42^(1/12)-1))+E42 -> 17.268532 | I42: =(G42/B42)*100 -> 67.192732 | J42: 90
B43: 25.7 | C43: 46539 | F43: 1.08 | G43: =G42*(1+(F43^(1/12)-1))+E43 -> 17.379638 | I43: =(G43/B43)*100 -> 67.625052 | J43: 90
B44: 25.7 | C44: 46569 | F44: 1.08 | G44: =G43*(1+(F44^(1/12)-1))+E44 -> 17.491459 | I44: =(G44/B44)*100 -> 68.060153 | J44: 90
B45: 25.7 | C45: 46600 | F45: 1.08 | G45: =G44*(1+(F45^(1/12)-1))+E45 -> 17.604 | I45: =(G45/B45)*100 -> 68.498054 | J45: 90
... B85: 25.7 | C85: 47818 | F85: 1.08 | G85: =G84*(1+(F85^(1/12)-1))+E85 -> 22.752225 | I85: =(G85/B85)*100 -> 88.530059 | J85: 90

Sheet Denver (HX)
A1: Denver (12% YoY) | B1: Total Storage | C1: Month | D1: In Use | E1: Change (TB) | F1: Growth (%) | G1: Forecast | H1: In use (%) | I1: Forecast (%) | J1: Max %
A2: HyperFlex | B2: =25.7 -> 25.7 | C2: 44562 | D2: ='Data Collection Sheet'!I$124 -> 12.65 | H2: =(D2/B2)*100 -> 49.22179 | J2: 75
B3: =25.7 -> 25.7 | C3: 44593 | D3: ='Data Collection Sheet'!J$124 -> 12.75 | H3: =(D3/B3)*100 -> 49.610895 | J3: 75
B4: =25.7 -> 25.7 | C4: 44621 | D4: ='Data Collection Sheet'!K$124 -> 12.85 | H4: =(D4/B4)*100 -> 50 | J4: 75
B5: =25.7 -> 25.7 | C5: 44652 | D5: ='Data Collection Sheet'!L$124 -> 12.3874 | H5: =(D5/B5)*100 -> 48.2 | J5: 75
B6: =25.7 -> 25.7 | C6: 44682 | D6: ='Data Collection Sheet'!M$124 -> 12.4 | H6: =(D6/B6)*100 -> 48.249027 | J6: 75
A7: Add 10TB Marketing (option-Consumer NAS) | B7: =25.7 -> 25.7 | C7: 44713 | D7: ='Data Collection Sheet'!N$124 -> 12.6 | H7: =(D7/B7)*100 -> 49.027237 | J7: 75
B8: =25.7 -> 25.7 | C8: 44743 | D8: ='Data Collection Sheet'!O$124 -> 12.8 | H8: =(D8/B8)*100 -> 49.805447 | J8: 75
B9: =25.7 -> 25.7 | C9: 44774 | D9: ='Data Collection Sheet'!P$124 -> 11.4 | H9: =(D9/B9)*100 -> 44.357977 | J9: 75
B10: =25.7 -> 25.7 | C10: 44805 | D10: ='Data Collection Sheet'!Q$124 -> 11.8 | H10: =(D10/B10)*100 -> 45.914397 | J10: 75
B11: =25.7 -> 25.7 | C11: 44835 | D11: ='Data Collection Sheet'!R$124 -> 12 | H11: =(D11/B11)*100 -> 46.692607 | J11: 75
B12: =25.7 -> 25.7 | C12: 44866 | D12: ='Data Collection Sheet'!S$124 -> 12.1 | H12: =(D12/B12)*100 -> 47.081712 | J12: 75
B13: =25.7 -> 25.7 | C13: 44896 | D13: ='Data Collection Sheet'!T$124 -> 12.5 | H13: =(D13/B13)*100 -> 48.638132 | J13: 75
B14: =25.7 -> 25.7 | C14: 44927 | D14: ='Data Collection Sheet'!U$124 -> 12.2 | H14: =(D14/B14)*100 -> 47.470817 | J14: 75
B15: =25.7 -> 25.7 | C15: 44958 | D15: ='Data Collection Sheet'!V$124 -> 12.3 | H15: =(D15/B15)*100 -> 47.859922 | J15: 75
B16: =25.7 -> 25.7 | C16: 44986 | D16: ='Data Collection Sheet'!W$124 -> 12 | H16: =(D16/B16)*100 -> 46.692607 | J16: 75
B17: =25.7 -> 25.7 | C17: 45017 | D17: ='Data Collection Sheet'!X$124 -> 11.9 | H17: =(D17/B17)*100 -> 46.303502 | J17: 75
B18: =25.7 -> 25.7 | C18: 45047 | D18: ='Data Collection Sheet'!Y$124 -> 12.1 | H18: =(D18/B18)*100 -> 47.081712 | J18: 75
B19: =25.7 -> 25.7 | C19: 45078 | D19: ='Data Collection Sheet'!Z$124 -> 11.2 | H19: =(D19/B19)*100 -> 43.579767 | J19: 75
B20: =25.7 -> 25.7 | C20: 45108 | D20: ='Data Collection Sheet'!AA$124 -> 11.5 | H20: =(D20/B20)*100 -> 44.747082 | J20: 75
B21: =25.7 -> 25.7 | C21: 45139 | D21: ='Data Collection Sheet'!AB$124 -> 11.7 | H21: =(D21/B21)*100 -> 45.525292 | J21: 75
B22: =25.7 -> 25.7 | C22: 45170 | D22: ='Data Collection Sheet'!AC$124 -> 12 | H22: =(D22/B22)*100 -> 46.692607 | J22: 75
B23: =25.7 -> 25.7 | C23: 45200 | D23: ='Data Collection Sheet'!AD$124 -> 12.2 | H23: =(D23/B23)*100 -> 47.470817 | J23: 75
B24: =25.7 -> 25.7 | C24: 45231 | D24: ='Data Collection Sheet'!AE$124 -> 12.5 | H24: =(D24/B24)*100 -> 48.638132 | J24: 75
B25: =25.7 -> 25.7 | C25: 45261 | D25: ='Data Collection Sheet'!AF$124 -> 12.6 | H25: =(D25/B25)*100 -> 49.027237 | J25: 75
B26: =25.7 -> 25.7 | C26: 45292 | D26: ='Data Collection Sheet'!AG$124 -> 12.2 | H26: =(D26/B26)*100 -> 47.470817 | J26: 75
B27: =25.7 -> 25.7 | C27: 45323 | D27: ='Data Collection Sheet'!AH$124 -> 12.5 | H27: =(D27/B27)*100 -> 48.638132 | J27: 75
B28: =25.7 -> 25.7 | C28: 45352 | D28: ='Data Collection Sheet'!AI$124 -> 12.4 | H28: =(D28/B28)*100 -> 48.249027 | J28: 75
B29: =25.7 -> 25.7 | C29: 45383 | D29: ='Data Collection Sheet'!AJ$124 -> 12.3 | H29: =(D29/B29)*100 -> 47.859922 | J29: 75
B30: =25.7 -> 25.7 | C30: 45413 | D30: ='Data Collection Sheet'!AK$124 -> 11.9 | H30: =(D30/B30)*100 -> 46.303502 | J30: 75
A31: Rehydrate 8TB from CV-archive | B31: =25.7 -> 25.7 | C31: 45444 | D31: ='Data Collection Sheet'!AL$124 -> 11.6 | H31: =(D31/B31)*100 -> 45.136187 | J31: 75
B32: =25.7 -> 25.7 | C32: 45474 | D32: ='Data Collection Sheet'!AM$124 -> 11.7 | H32: =(D32/B32)*100 -> 45.525292 | J32: 75
B33: =25.7 -> 25.7 | C33: 45505 | D33: ='Data Collection Sheet'!AN$124 -> 11.9 | H33: =(D33/B33)*100 -> 46.303502 | J33: 75
B34: =25.7 -> 25.7 | C34: 45536 | D34: ='Data Collection Sheet'!AO$124 -> 11.9 | H34: =(D34/B34)*100 -> 46.303502 | J34: 75
A35: from 12% to 8% increase | B35: =25.7 -> 25.7 | C35: 45566 | D35: ='Data Collection Sheet'!AP$124 -> 12.3 | H35: =(D35/B35)*100 -> 47.859922 | J35: 75
B36: =25.7 -> 25.7 | C36: 45597 | D36: ='Data Collection Sheet'!AQ$124 -> 12.4 | H36: =(D36/B36)*100 -> 48.249027 | J36: 75
B37: =25.7 -> 25.7 | C37: 45627 | D37: ='Data Collection Sheet'!AR$124 -> 12.6 | H37: =(D37/B37)*100 -> 49.027237 | J37: 75
B38: =25.7 -> 25.7 | C38: 45658 | D38: ='Data Collection Sheet'!AS$124 -> 12.6 | H38: =(D38/B38)*100 -> 49.027237 | J38: 75
B39: =25.7 -> 25.7 | C39: 45689 | D39: ='Data Collection Sheet'!AT$124 -> 12.8 | H39: =(D39/B39)*100 -> 49.805447 | J39: 75
B40: =25.7 -> 25.7 | C40: 45717 | D40: ='Data Collection Sheet'!AU$124 -> 12.8 | H40: =(D40/B40)*100 -> 49.805447 | J40: 75
...

Sheet Denver (ESX)
